Workbook
Name _MinPctMsvInRoi: #REF!
Name _MinPctMsvOutROI: #REF!
Name _MinTripsInROI: #REF!
Name _MinTripsOutROI: #REF!
Name _MsvPct: #REF!
Name _ScoFylYr_1: #REF!
Name _ScoFylYr_2: #REF!
Name _ScoFylYr_3: #REF!
Name _ScoFylYr_4: #REF!

Sheet Sheet1
A1: Table 1
A2: Hernando County Concurrency Management System
A3: Tier I Test: To Determine Concurrency or Need for Additional Analysis
A4: Version: 11/19/2022, Valid 12/01/2022 to 12/01/2024, unless superseded
AY12: Y
A13: Notes: | AY13: N
A14: 1) In the Lanes/Type columns, "0" indicates that the segment does not exist in existing or future years.
A17: General Information | F17: Lanes/Type | I17: Hurricane Evacuation Route | J17: Strategic Intermodal System | K17: Growth | N17: AADT (Daily Volumes) | R17: K Factor | S17: Segment Peak Hour Two Way Volumes | W17: Net New External Project Traffic | X17: Total External Project Traffic | Y17: Facility Level of Service (LOS) | AE17: Facility Maximum Service Volume (MSV) Peak Hour Two Way | AM17: Conceptual Analysis Required (V:MSV > 90%) Base Traffic + 3 or 5 Year Growth + Project Traffic | AY17: Witihin Radius of Influence | AZ17: On Study Network | BA17: Trips Added as Percent of MSV | BB17: Seg Fails Yr 0 Status | BC17: Fac. Fails Yr 0 Status | BD17: Seg Fails Yr 2 Status | BE17: Fac. Fails Yr 2 Status | BF17: Seg Fails Yr 3 Status | BG17: Fac Fails Yr 3 Status | BH17: Seg Fails Yr 4 Status | BI17: Fac Fails Yr 4 Status | BJ17: % Distribution | BK17: Working Fields
A18: Segment ID | B18: =IF(_ScoFylYr_4>0,"Facility ID ("& _ScoFylYr_4 & ")", "") -> #REF! | C18: On Street | D18: From Street | E18: To Street | F18: Existing Number of Lanes and Type | G18: =IF(#REF! >0,#REF! & " RT and Type","") -> #NAME? | H18: Programmed Improvements | K18: Base Year Volume | L18: Base Year of Count | M18: Annual Growth Rate | N18: AADT (2020) | O18: AADT (2023) | P18: AADT (2025) | Q18: =IF(_ScoFylYr_4 > 0, "AADT (" & _ScoFylYr_4 & ")","") -> #REF! | S18: 2020 | T18: 2023 | U18: 2025 | V18: =IF(_ScoFylYr_4>0,_ScoFylYr_4,"") -> #REF! | Y18: LOS Method | Z18: LOS Standard | AA18: =IF(_ScoFylYr_1>0, "LOS (" & _ScoFylYr_1 &")","") -> #REF! | AB18: =IF(_ScoFylYr_2>0, "LOS (" & _ScoFylYr_2 &")","") -> #REF! | AC18: =IF(_ScoFylYr_3>0, "LOS (" & _ScoFylYr_3 &")","") -> #REF! | AD18: =IF(_ScoFylYr_4>0, "LOS (" & _ScoFylYr_4 &")","") -> #REF! | AE18: MSV 2020 | AF18: =IF(AE18<>"", _MsvPct * 100 & "% of "& AE18,"") -> #REF! | AG18: MSV (2023) | AH18: =IF(AG18<>"",_MsvPct * 100 & "% of "& AG18,"") -> #REF! | AI18: MSV (2025) | AJ18: =IF(AI18<>"",_MsvPct * 100 & "% of "& AI18,"") -> #REF! | AK18: =IF(_ScoFylYr_4>0, "MSV (" & _ScoFylYr_4 & ")","") -> #REF! | AL18: =IF(AK18<>"",_MsvPct * 100 & "% of "& AK18,"") -> #REF! | AM18: 2020 Volume Total | AN18: 2020 V/MSV Ratio | AO18: 2020 Status | AP18: 2023 Volume Total | AQ18: 2023 V/MSV Ratio | AR18: 2023 Status | AS18: 2025 Volume Total | AT18: 2025 V/MSV Ratio | AU18: 2025 Status | AV18: =IF(_ScoFylYr_4>0, _ScoFylYr_4 &" Volume Total","") -> #REF! | AW18: =IF(_ScoFylYr_4>0, _ScoFylYr_4 &" V/MSV Ratio","") -> #REF! | AX18: =IF(_ScoFylYr_4>0, _ScoFylYr_4 &" Status","") -> #REF! | BK18: 1 | BL18: =BK18+1 -> 2 | BM18: =BL18+1 -> 3 | BN18: =BM18+1 -> 4 | BO18: =BN18+1 -> 5 | BP18: =BO18+1 -> 6 | BQ18: =BP18+1 -> 7 | BR18: =BQ18+1 -> 8 | BS18: =BR18+1 -> 9 | ... CD18: =CC18+1 -> 20
A19: A | B19: B4 | C19: C | D19: D | E19: E | F19: F | H19: G | I19: H | J19: I | K19: K | L19: L | M19: M | N19: J | O19: K | P19: L | Q19: Q | R19: M | S19: N | T19: O | U19: P | V19: V | W19: W1 | X19: W2 | Y19: Q | Z19: R | AE19: S | AG19: T | AI19: U | AK19: AC | AM19: AA | AN19: AB | AO19: AC | AP19: AD | AQ19: AE | AR19: AF | AS19: AG | AT19: AH | AU19: AI | AV19: AM | AW19: AN | AX19: AO | AY19: W3 | AZ19: W4 | BA19: AR | BJ19: W5
A20: 10810 | C20: TREIMAN BLVD (US301/SR35) | D20: PASCO COUNTY LINE | E20: CORTEZ BLVD (SR50) | F20: 2U | H20: 2U | I20: Y | J20: N | N20: 6936 | O20: 7023 | P20: 7287 | R20: 0.09 | S20: 624 | T20: 632 | U20: 656 | V20: =ROUND(R20*Q20,0) -> 0 | Y20: GEN. TABLES | Z20: ='[1]Tier 1'!V20 -> C | AE20: ='[1]Tier 1'!W20 -> 1490 | AG20: ='[1]Tier 1'!X20 -> 1490 | AI20: ='[1]Tier 1'!Y20 -> 4020 | AJ20: =AI20 * 0.9 -> 3618 | AK20: =VLOOKUP(A20,#REF!,-1,FALSE) -> #REF! | AL20: =AK20 * 0.9 -> #REF! | AM20: =S20+W20 -> 624 | AN20: =IF(AE20>0, ROUND(AM20/AE20,3),0) -> 0.419 | AO20: =IF($W20>0,IF(AN20>0.8999,"Study 1", "OK"),"OK") -> OK | AP20: =T20+W20 -> 632 | AQ20: =IF(AG20>0, ROUND(AP20/AG20,3),0) -> 0.424 | AR20: =IF($W20>0,IF(AQ20>0.8999,"Study 1", "OK"),"OK") -> OK | AS20: =U20+W20 -> 656 | AT20: =IF(AI20>0, ROUND(AS20/AI20,3),0) -> 0.163 | AU20: =IF($W20>0,IF(AT20>0.8999,"Study 1", "OK"),"OK") -> OK | AV20: =V20+W20 -> 0 | AW20: =IF(AK20>0, ROUND(AV20/AK20,3),0) -> #REF! | AX20: =IF(AND(V20=0, AV20>0), "DATA1", IF(OR(AV20>AL20,BI20>0), IF(Y20="CONC. (ART-PLAN)", "STUDY 1", "STUDY 2"), "OK")) -> #REF! | BA20: =IF(AG20>0, X20/AG20, 0) -> 0 | BB20: =IF(AM20>AF20,1,0) -> 1 | BC20: =SUMIF(#REF!,#REF!, BB20:BB333) -> #REF! | BD20: =IF(AP20>AH20,1,0) -> 1 | BE20: =SUMIF(#REF!,#REF!, BD20:BD333) -> #REF! | BF20: =IF(AS20>AJ20,1,0) -> 0 | BG20: =SUMIF(#REF!,#REF!, BF20:BF333) -> #REF! | BH20: =IF(AV20>AL20,1,0) -> #REF! | BI20: =SUMIF(B20:B333, B20, BH20:BH333) -> 0
A21: 10820 | C21: TREIMAN BLVD (US301/SR35) | D21: CORTEZ BLVD (SR50) | E21: RIDGE MANOR BLVD | F21: 2U | H21: 2U | I21: Y | J21: N | N21: 7752 | O21: 8199 | P21: 8669 | R21: 0.09 | S21: 698 | T21: 738 | U21: 780 | V21: =ROUND(R21*Q21,0) -> 0 | Y21: GEN. TABLES | Z21: ='[1]Tier 1'!V21 -> C | AE21: ='[1]Tier 1'!W21 -> 820 | AG21: ='[1]Tier 1'!X21 -> 820 | AI21: ='[1]Tier 1'!Y21 -> 820 | AJ21: =AI21 * 0.9 -> 738 | AK21: =VLOOKUP(A21,#REF!,-1,FALSE) -> #REF! | AL21: =AK21 * 0.9 -> #REF! | AM21: =S21+W21 -> 698 | AN21: =IF(AE21>0, ROUND(AM21/AE21,3),0) -> 0.851 | AO21: =IF($W21>0,IF(AN21>0.8999,"Study 1", "OK"),"OK") -> OK | AP21: =T21+W21 -> 738 | AQ21: =IF(AG21>0, ROUND(AP21/AG21,3),0) -> 0.9 | AR21: =IF($W21>0,IF(AQ21>0.8999,"Study 1", "OK"),"OK") -> OK | AS21: =U21+W21 -> 780 | AT21: =IF(AI21>0, ROUND(AS21/AI21,3),0) -> 0.951 | AU21: =IF($W21>0,IF(AT21>0.8999,"Study 1", "OK"),"OK") -> OK | AV21: =V21+W21 -> 0 | AW21: =IF(AK21>0, ROUND(AV21/AK21,3),0) -> #REF! | AX21: =IF(AND(V21=0, AV21>0), "DATA1", IF(OR(AV21>AL21,BI21>0), IF(Y21="CONC. (ART-PLAN)", "STUDY 1", "STUDY 2"), "OK")) -> #REF! | BA21: =IF(AG21>0, X21/AG21, 0) -> 0 | BB21: =IF(AM21>AF21,1,0) -> 1 | BC21: =SUMIF(#REF!,#REF!, BB20:BB333) -> #REF! | BD21: =IF(AP21>AH21,1,0) -> 1 | BE21: =SUMIF(#REF!,#REF!, BD20:BD333) -> #REF! | BF21: =IF(AS21>AJ21,1,0) -> 1 | BG21: =SUMIF(#REF!,#REF!, BF20:BF333) -> #REF! | BH21: =IF(AV21>AL21,1,0) -> #REF! | BI21: =SUMIF(B20:B333, B21, BH20:BH333) -> 0
A22: 10830 | C22: TREIMAN BLVD (US301/SR35) | D22: RIDGE MANOR BLVD | E22: SUMTER COUNTY LINE | F22: 2U | H22: 4D | I22: Y | J22: N | N22: 4896 | O22: 5063 | P22: 5327 | R22: 0.09 | S22: 441 | T22: 456 | U22: 479 | V22: =ROUND(R22*Q22,0) -> 0 | Y22: GEN. TABLES | Z22: ='[1]Tier 1'!V22 -> C | AE22: ='[1]Tier 1'!W22 -> 1490 | AG22: ='[1]Tier 1'!X22 -> 1490 | AI22: ='[1]Tier 1'!Y22 -> 1490 | AJ22: =AI22 * 0.9 -> 1341 | AK22: =VLOOKUP(A22,#REF!,-1,FALSE) -> #REF! | AL22: =AK22 * 0.9 -> #REF! | AM22: =S22+W22 -> 441 | AN22: =IF(AE22>0, ROUND(AM22/AE22,3),0) -> 0.296 | AO22: =IF($W22>0,IF(AN22>0.8999,"Study 1", "OK"),"OK") -> OK | AP22: =T22+W22 -> 456 | AQ22: =IF(AG22>0, ROUND(AP22/AG22,3),0) -> 0.306 | AR22: =IF($W22>0,IF(AQ22>0.8999,"Study 1", "OK"),"OK") -> OK | AS22: =U22+W22 -> 479 | AT22: =IF(AI22>0, ROUND(AS22/AI22,3),0) -> 0.321 | AU22: =IF($W22>0,IF(AT22>0.8999,"Study 1", "OK"),"OK") -> OK | AV22: =V22+W22 -> 0 | AW22: =IF(AK22>0, ROUND(AV22/AK22,3),0) -> #REF! | AX22: =IF(AND(V22=0, AV22>0), "DATA1", IF(OR(AV22>AL22,BI22>0), IF(Y22="CONC. (ART-PLAN)", "STUDY 1", "STUDY 2"), "OK")) -> #REF! | BA22: =IF(AG22>0, X22/AG22, 0) -> 0 | BB22: =IF(AM22>AF22,1,0) -> 1 | BC22: =SUMIF(#REF!,#REF!, BB20:BB333) -> #REF! | BD22: =IF(AP22>AH22,1,0) -> 1 | BE22: =SUMIF(#REF!,#REF!, BD20:BD333) -> #REF! | BF22: =IF(AS22>AJ22,1,0) -> 0 | BG22: =SUMIF(#REF!,#REF!, BF20:BF333) -> #REF! | BH22: =IF(AV22>AL22,1,0) -> #REF! | BI22: =SUMIF(B20:B333, B22, BH20:BH333) -> 0
A23: 10060 | C23: BROAD ST (US41/SR45) | D23: COUNTY LINE RD | E23: AYERS RD | F23: 2U | H23: 4D | I23: Y | J23: N | N23: 15120 | O23: 16527 | P23: 17465 | R23: 0.09 | S23: 1361 | T23: 1487 | U23: 1572 | V23: =ROUND(R23*Q23,0) -> 0 | Y23: GEN. TABLES | Z23: ='[1]Tier 1'!V23 -> C | AE23: ='[1]Tier 1'!W23 -> 1510 | AG23: ='[1]Tier 1'!X23 -> 1510 | AI23: ='[1]Tier 1'!Y23 -> 1510 | AJ23: =AI23 * 0.9 -> 1359 | AK23: =VLOOKUP(A23,#REF!,-1,FALSE) -> #REF! | AL23: =AK23 * 0.9 -> #REF! | AM23: =S23+W23 -> 1361 | AN23: =IF(AE23>0, ROUND(AM23/AE23,3),0) -> 0.901 | AO23: =IF($W23>0,IF(AN23>0.8999,"Study 1", "OK"),"OK") -> OK | AP23: =T23+W23 -> 1487 | AQ23: =IF(AG23>0, ROUND(AP23/AG23,3),0) -> 0.985 | AR23: =IF($W23>0,IF(AQ23>0.8999,"Study 1", "OK"),"OK") -> OK | AS23: =U23+W23 -> 1572 | AT23: =IF(AI23>0, ROUND(AS23/AI23,3),0) -> 1.041 | AU23: =IF($W23>0,IF(AT23>0.8999,"Study 1", "OK"),"OK") -> OK | AV23: =V23+W23 -> 0 | AW23: =IF(AK23>0, ROUND(AV23/AK23,3),0) -> #REF! | AX23: =IF(AND(V23=0, AV23>0), "DATA1", IF(OR(AV23>AL23,BI23>0), IF(Y23="CONC. (ART-PLAN)", "STUDY 1", "STUDY 2"), "OK")) -> #REF! | BA23: =IF(AG23>0, X23/AG23, 0) -> 0 | BB23: =IF(AM23>AF23,1,0) -> 1 | BC23: =SUMIF(#REF!,#REF!, BB20:BB333) -> #REF! | BD23: =IF(AP23>AH23,1,0) -> 1 | BE23: =SUMIF(#REF!,#REF!, BD20:BD333) -> #REF! | BF23: =IF(AS23>AJ23,1,0) -> 1 | BG23: =SUMIF(#REF!,#REF!, BF20:BF333) -> #REF! | BH23: =IF(AV23>AL23,1,0) -> #REF! | BI23: =SUMIF(B20:B333, B23, BH20:BH333) -> 0
A24: 10070.1 | C24: BROAD ST (US41/SR45) | D24: AYERS RD | E24: SGT LEA MILLS BLVD | F24: 4D | H24: 4D | I24: Y | J24: N | N24: 15360 | O24: 16484 | P24: 17233 | R24: 0.09 | S24: 1382 | T24: 1484 | U24: 1551 | V24: =ROUND(R24*Q24,0) -> 0 | Y24: GEN. TABLES | Z24: ='[1]Tier 1'!V24 -> C | AE24: ='[1]Tier 1'!W24 -> 3420 | AG24: ='[1]Tier 1'!X24 -> 3420 | AI24: ='[1]Tier 1'!Y24 -> 3420 | AJ24: =AI24 * 0.9 -> 3078 | AK24: =VLOOKUP(A24,#REF!,-1,FALSE) -> #REF! | AL24: =AK24 * 0.9 -> #REF! | AM24: =S24+W24 -> 1382 | AN24: =IF(AE24>0, ROUND(AM24/AE24,3),0) -> 0.404 | AO24: =IF($W24>0,IF(AN24>0.8999,"Study 1", "OK"),"OK") -> OK | AP24: =T24+W24 -> 1484 | AQ24: =IF(AG24>0, ROUND(AP24/AG24,3),0) -> 0.434 | AR24: =IF($W24>0,IF(AQ24>0.8999,"Study 1", "OK"),"OK") -> OK | AS24: =U24+W24 -> 1551 | AT24: =IF(AI24>0, ROUND(AS24/AI24,3),0) -> 0.454 | AU24: =IF($W24>0,IF(AT24>0.8999,"Study 1", "OK"),"OK") -> OK | AV24: =V24+W24 -> 0 | AW24: =IF(AK24>0, ROUND(AV24/AK24,3),0) -> #REF! | AX24: =IF(AND(V24=0, AV24>0), "DATA1", IF(OR(AV24>AL24,BI24>0), IF(Y24="CONC. (ART-PLAN)", "STUDY 1", "STUDY 2"), "OK")) -> #REF! | BA24: =IF(AG24>0, X24/AG24, 0) -> 0 | BB24: =IF(AM24>AF24,1,0) -> 1 | BC24: =SUMIF(#REF!,#REF!, BB20:BB333) -> #REF! | BD24: =IF(AP24>AH24,1,0) -> 1 | BE24: =SUMIF(#REF!,#REF!, BD20:BD333) -> #REF! | BF24: =IF(AS24>AJ24,1,0) -> 0 | BG24: =SUMIF(#REF!,#REF!, BF20:BF333) -> #REF! | BH24: =IF(AV24>AL24,1,0) -> #REF! | BI24: =SUMIF(B20:B333, B24, BH20:BH333) -> 0
A25: 10070.2 | C25: BROAD ST (US41/SR45) | D25: SGT LEA MILLS BLVD | E25: SPRING HILL DR | F25: 4D | H25: 6D | I25: Y | J25: N | N25: 15360 | O25: 16484 | P25: 17233 | R25: 0.09 | S25: 1382 | T25: 1484 | U25: 1551 | V25: =ROUND(R25*Q25,0) -> 0 | Y25: GEN. TABLES | Z25: ='[1]Tier 1'!V25 -> C | AE25: ='[1]Tier 1'!W25 -> 3420 | AG25: ='[1]Tier 1'!X25 -> 3420 | AI25: ='[1]Tier 1'!Y25 -> 3420 | AJ25: =AI25 * 0.9 -> 3078 | AK25: =VLOOKUP(A25,#REF!,-1,FALSE) -> #REF! | AL25: =AK25 * 0.9 -> #REF! | AM25: =S25+W25 -> 1382 | AN25: =IF(AE25>0, ROUND(AM25/AE25,3),0) -> 0.404 | AO25: =IF($W25>0,IF(AN25>0.8999,"Study 1", "OK"),"OK") -> OK | AP25: =T25+W25 -> 1484 | AQ25: =IF(AG25>0, ROUND(AP25/AG25,3),0) -> 0.434 | AR25: =IF($W25>0,IF(AQ25>0.8999,"Study 1", "OK"),"OK") -> OK | AS25: =U25+W25 -> 1551 | AT25: =IF(AI25>0, ROUND(AS25/AI25,3),0) -> 0.454 | AU25: =IF($W25>0,IF(AT25>0.8999,"Study 1", "OK"),"OK") -> OK | AV25: =V25+W25 -> 0 | AW25: =IF(AK25>0, ROUND(AV25/AK25,3),0) -> #REF! | AX25: =IF(AND(V25=0, AV25>0), "DATA1", IF(OR(AV25>AL25,BI25>0), IF(Y25="CONC. (ART-PLAN)", "STUDY 1", "STUDY 2"), "OK")) -> #REF! | BA25: =IF(AG25>0, X25/AG25, 0) -> 0 | BB25: =IF(AM25>AF25,1,0) -> 1 | BC25: =SUMIF(#REF!,#REF!, BB20:BB333) -> #REF! | BD25: =IF(AP25>AH25,1,0) -> 1 | BE25: =SUMIF(#REF!,#REF!, BD20:BD333) -> #REF! | BF25: =IF(AS25>AJ25,1,0) -> 0 | BG25: =SUMIF(#REF!,#REF!, BF20:BF333) -> #REF! | BH25: =IF(AV25>AL25,1,0) -> #REF! | BI25: =SUMIF(B20:B333, B25, BH20:BH333) -> 0
A26: 10080 | C26: BROAD ST (US41/SR45) | D26: SPRING HILL DR | E26: POWELL RD | F26: 4D | H26: 6D | I26: Y | J26: N | N26: 22093 | O26: 24130 | P26: 25487 | R26: 0.09 | S26: 1988 | T26: 2172 | U26: 2294 | V26: =ROUND(R26*Q26,0) -> 0 | Y26: GEN. TABLES | Z26: ='[1]Tier 1'!V26 -> C | AE26: ='[1]Tier 1'!W26 -> 3420 | AG26: ='[1]Tier 1'!X26 -> 3420 | AI26: ='[1]Tier 1'!Y26 -> 3420 | AJ26: =AI26 * 0.9 -> 3078 | AK26: =VLOOKUP(A26,#REF!,-1,FALSE) -> #REF! | AL26: =AK26 * 0.9 -> #REF! | AM26: =S26+W26 -> 1988 | AN26: =IF(AE26>0, ROUND(AM26/AE26,3),0) -> 0.581 | AO26: =IF($W26>0,IF(AN26>0.8999,"Study 1", "OK"),"OK") -> OK | AP26: =T26+W26 -> 2172 | AQ26: =IF(AG26>0, ROUND(AP26/AG26,3),0) -> 0.635 | AR26: =IF($W26>0,IF(AQ26>0.8999,"Study 1", "OK"),"OK") -> OK | AS26: =U26+W26 -> 2294 | AT26: =IF(AI26>0, ROUND(AS26/AI26,3),0) -> 0.671 | AU26: =IF($W26>0,IF(AT26>0.8999,"Study 1", "OK"),"OK") -> OK | AV26: =V26+W26 -> 0 | AW26: =IF(AK26>0, ROUND(AV26/AK26,3),0) -> #REF! | AX26: =IF(AND(V26=0, AV26>0), "DATA1", IF(OR(AV26>AL26,BI26>0), IF(Y26="CONC. (ART-PLAN)", "STUDY 1", "STUDY 2"), "OK")) -> #REF! | BA26: =IF(AG26>0, X26/AG26, 0) -> 0 | BB26: =IF(AM26>AF26,1,0) -> 1 | BC26: =SUMIF(#REF!,#REF!, BB20:BB333) -> #REF! | BD26: =IF(AP26>AH26,1,0) -> 1 | BE26: =SUMIF(#REF!,#REF!, BD20:BD333) -> #REF! | BF26: =IF(AS26>AJ26,1,0) -> 0 | BG26: =SUMIF(#REF!,#REF!, BF20:BF333) -> #REF! | BH26: =IF(AV26>AL26,1,0) -> #REF! | BI26: =SUMIF(B20:B333, B26, BH20:BH333) -> 0
A27: 10090 | C27: BROAD ST (US41/SR45) | D27: POWELL RD | E27: PINE CABIN RD | F27: 6D | H27: 6D | I27: Y | J27: N | N27: 25073 | O27: 26772 | P27: 27904 | R27: 0.09 | S27: 2257 | T27: 2409 | U27: 2511 | V27: =ROUND(R27*Q27,0) -> 0 | Y27: GEN. TABLES | Z27: ='[1]Tier 1'!V27 -> C | AE27: ='[1]Tier 1'!W27 -> 5250 | AG27: ='[1]Tier 1'!X27 -> 5250 | AI27: ='[1]Tier 1'!Y27 -> 5250 | AJ27: =AI27 * 0.9 -> 4725 | AK27: =VLOOKUP(A27,#REF!,-1,FALSE) -> #REF! | AL27: =AK27 * 0.9 -> #REF! | AM27: =S27+W27 -> 2257 | AN27: =IF(AE27>0, ROUND(AM27/AE27,3),0) -> 0.43 | AO27: =IF($W27>0,IF(AN27>0.8999,"Study 1", "OK"),"OK") -> OK | AP27: =T27+W27 -> 2409 | AQ27: =IF(AG27>0, ROUND(AP27/AG27,3),0) -> 0.459 | AR27: =IF($W27>0,IF(AQ27>0.8999,"Study 1", "OK"),"OK") -> OK | AS27: =U27+W27 -> 2511 | AT27: =IF(AI27>0, ROUND(AS27/AI27,3),0) -> 0.478 | AU27: =IF($W27>0,IF(AT27>0.8999,"Study 1", "OK"),"OK") -> OK | AV27: =V27+W27 -> 0 | AW27: =IF(AK27>0, ROUND(AV27/AK27,3),0) -> #REF! | AX27: =IF(AND(V27=0, AV27>0), "DATA1", IF(OR(AV27>AL27,BI27>0), IF(Y27="CONC. (ART-PLAN)", "STUDY 1", "STUDY 2"), "OK")) -> #REF! | BA27: =IF(AG27>0, X27/AG27, 0) -> 0 | BB27: =IF(AM27>AF27,1,0) -> 1 | BC27: =SUMIF(#REF!,#REF!, BB20:BB333) -> #REF! | BD27: =IF(AP27>AH27,1,0) -> 1 | BE27: =SUMIF(#REF!,#REF!, BD20:BD333) -> #REF! | BF27: =IF(AS27>AJ27,1,0) -> 0 | BG27: =SUMIF(#REF!,#REF!, BF20:BF333) -> #REF! | BH27: =IF(AV27>AL27,1,0) -> #REF! | BI27: =SUMIF(B20:B333, B27, BH20:BH333) -> 0
A28: 10100 | C28: BROAD ST (US41/SR45) | D28: PINE CABIN RD | E28: HENNES COVE | F28: 6D | H28: 6D | I28: Y | J28: N | N28: 25073 | O28: 26772 | P28: 27904 | R28: 0.09 | S28: 2257 | T28: 2409 | U28: 2511 | V28: =ROUND(R28*Q28,0) -> 0 | Y28: GEN. TABLES | Z28: ='[1]Tier 1'!V28 -> C | AE28: ='[1]Tier 1'!W28 -> 5250 | AG28: ='[1]Tier 1'!X28 -> 5250 | AI28: ='[1]Tier 1'!Y28 -> 5250 | AJ28: =AI28 * 0.9 -> 4725 | AK28: =VLOOKUP(A28,#REF!,-1,FALSE) -> #REF! | AL28: =AK28 * 0.9 -> #REF! | AM28: =S28+W28 -> 2257 | AN28: =IF(AE28>0, ROUND(AM28/AE28,3),0) -> 0.43 | AO28: =IF($W28>0,IF(AN28>0.8999,"Study 1", "OK"),"OK") -> OK | AP28: =T28+W28 -> 2409 | AQ28: =IF(AG28>0, ROUND(AP28/AG28,3),0) -> 0.459 | AR28: =IF($W28>0,IF(AQ28>0.8999,"Study 1", "OK"),"OK") -> OK | AS28: =U28+W28 -> 2511 | AT28: =IF(AI28>0, ROUND(AS28/AI28,3),0) -> 0.478 | AU28: =IF($W28>0,IF(AT28>0.8999,"Study 1", "OK"),"OK") -> OK | AV28: =V28+W28 -> 0 | AW28: =IF(AK28>0, ROUND(AV28/AK28,3),0) -> #REF! | AX28: =IF(AND(V28=0, AV28>0), "DATA1", IF(OR(AV28>AL28,BI28>0), IF(Y28="CONC. (ART-PLAN)", "STUDY 1", "STUDY 2"), "OK")) -> #REF! | BA28: =IF(AG28>0, X28/AG28, 0) -> 0 | BB28: =IF(AM28>AF28,1,0) -> 1 | BC28: =SUMIF(#REF!,#REF!, BB20:BB333) -> #REF! | BD28: =IF(AP28>AH28,1,0) -> 1 | BE28: =SUMIF(#REF!,#REF!, BD20:BD333) -> #REF! | BF28: =IF(AS28>AJ28,1,0) -> 0 | BG28: =SUMIF(#REF!,#REF!, BF20:BF333) -> #REF! | BH28: =IF(AV28>AL28,1,0) -> #REF! | BI28: =SUMIF(B20:B333, B28, BH20:BH333) -> 0
A29: 10110.1 | C29: BROAD ST (US41/SR45) | D29: HENNES COVE | E29: JOHN MARTIN LN | F29: 6D | H29: 6D | I29: Y | J29: N | N29: 25073 | O29: 26772 | P29: 27904 | R29: 0.09 | S29: 2257 | T29: 2409 | U29: 2511 | V29: =ROUND(R29*Q29,0) -> 0 | Y29: GEN. TABLES | Z29: ='[1]Tier 1'!V29 -> C | AE29: ='[1]Tier 1'!W29 -> 5250 | AG29: ='[1]Tier 1'!X29 -> 5250 | AI29: ='[1]Tier 1'!Y29 -> 5250 | AJ29: =AI29 * 0.9 -> 4725 | AK29: =VLOOKUP(A29,#REF!,-1,FALSE) -> #REF! | AL29: =AK29 * 0.9 -> #REF! | AM29: =S29+W29 -> 2257 | AN29: =IF(AE29>0, ROUND(AM29/AE29,3),0) -> 0.43 | AO29: =IF($W29>0,IF(AN29>0.8999,"Study 1", "OK"),"OK") -> OK | AP29: =T29+W29 -> 2409 | AQ29: =IF(AG29>0, ROUND(AP29/AG29,3),0) -> 0.459 | AR29: =IF($W29>0,IF(AQ29>0.8999,"Study 1", "OK"),"OK") -> OK | AS29: =U29+W29 -> 2511 | AT29: =IF(AI29>0, ROUND(AS29/AI29,3),0) -> 0.478 | AU29: =IF($W29>0,IF(AT29>0.8999,"Study 1", "OK"),"OK") -> OK | AV29: =V29+W29 -> 0 | AW29: =IF(AK29>0, ROUND(AV29/AK29,3),0) -> #REF! | AX29: =IF(AND(V29=0, AV29>0), "DATA1", IF(OR(AV29>AL29,BI29>0), IF(Y29="CONC. (ART-PLAN)", "STUDY 1", "STUDY 2"), "OK")) -> #REF! | BA29: =IF(AG29>0, X29/AG29, 0) -> 0 | BB29: =IF(AM29>AF29,1,0) -> 1 | BC29: =SUMIF(#REF!,#REF!, BB20:BB333) -> #REF! | BD29: =IF(AP29>AH29,1,0) -> 1 | BE29: =SUMIF(#REF!,#REF!, BD20:BD333) -> #REF! | BF29: =IF(AS29>AJ29,1,0) -> 0 | BG29: =SUMIF(#REF!,#REF!, BF20:BF333) -> #REF! | BH29: =IF(AV29>AL29,1,0) -> #REF! | BI29: =SUMIF(B20:B333, B29, BH20:BH333) -> 0
A30: 10110.2 | C30: BROAD ST (US41/SR45) | D30: JOHN MARTIN LN | E30: VFW RD | F30: 6D | H30: 6D | I30: Y | J30: N | N30: 25073 | O30: 26772 | P30: 27904 | R30: 0.09 | S30: 2257 | T30: 2409 | U30: 2511 | V30: =ROUND(R30*Q30,0) -> 0 | Y30: GEN. TABLES | Z30: ='[1]Tier 1'!V30 -> C | AE30: ='[1]Tier 1'!W30 -> 5250 | AG30: ='[1]Tier 1'!X30 -> 5250 | AI30: ='[1]Tier 1'!Y30 -> 5250 | AJ30: =AI30 * 0.9 -> 4725 | AK30: =VLOOKUP(A30,#REF!,-1,FALSE) -> #REF! | AL30: =AK30 * 0.9 -> #REF! | AM30: =S30+W30 -> 2257 | AN30: =IF(AE30>0, ROUND(AM30/AE30,3),0) -> 0.43 | AO30: =IF($W30>0,IF(AN30>0.8999,"Study 1", "OK"),"OK") -> OK | AP30: =T30+W30 -> 2409 | AQ30: =IF(AG30>0, ROUND(AP30/AG30,3),0) -> 0.459 | AR30: =IF($W30>0,IF(AQ30>0.8999,"Study 1", "OK"),"OK") -> OK | AS30: =U30+W30 -> 2511 | AT30: =IF(AI30>0, ROUND(AS30/AI30,3),0) -> 0.478 | AU30: =IF($W30>0,IF(AT30>0.8999,"Study 1", "OK"),"OK") -> OK | AV30: =V30+W30 -> 0 | AW30: =IF(AK30>0, ROUND(AV30/AK30,3),0) -> #REF! | AX30: =IF(AND(V30=0, AV30>0), "DATA1", IF(OR(AV30>AL30,BI30>0), IF(Y30="CONC. (ART-PLAN)", "STUDY 1", "STUDY 2"), "OK")) -> #REF! | BA30: =IF(AG30>0, X30/AG30, 0) -> 0 | BB30: =IF(AM30>AF30,1,0) -> 1 | BC30: =SUMIF(#REF!,#REF!, BB20:BB333) -> #REF! | BD30: =IF(AP30>AH30,1,0) -> 1 | BE30: =SUMIF(#REF!,#REF!, BD20:BD333) -> #REF! | BF30: =IF(AS30>AJ30,1,0) -> 0 | BG30: =SUMIF(#REF!,#REF!, BF20:BF333) -> #REF! | BH30: =IF(AV30>AL30,1,0) -> #REF! | BI30: =SUMIF(B20:B333, B30, BH20:BH333) -> 0
A31: 10115 | C31: BROAD ST (US41/SR45) | D31: VFW RD | E31: WISCON RD | F31: 6D | H31: 6D | I31: Y | J31: N | N31: 25073 | O31: 26772 | P31: 27904 | R31: 0.09 | S31: 2257 | T31: 2409 | U31: 2511 | V31: =ROUND(R31*Q31,0) -> 0 | Y31: GEN. TABLES | Z31: ='[1]Tier 1'!V31 -> C | AE31: ='[1]Tier 1'!W31 -> 5250 | AG31: ='[1]Tier 1'!X31 -> 5250 | AI31: ='[1]Tier 1'!Y31 -> 5250 | AJ31: =AI31 * 0.9 -> 4725 | AK31: =VLOOKUP(A31,#REF!,-1,FALSE) -> #REF! | AL31: =AK31 * 0.9 -> #REF! | AM31: =S31+W31 -> 2257 | AN31: =IF(AE31>0, ROUND(AM31/AE31,3),0) -> 0.43 | AO31: =IF($W31>0,IF(AN31>0.8999,"Study 1", "OK"),"OK") -> OK | AP31: =T31+W31 -> 2409 | AQ31: =IF(AG31>0, ROUND(AP31/AG31,3),0) -> 0.459 | AR31: =IF($W31>0,IF(AQ31>0.8999,"Study 1", "OK"),"OK") -> OK | AS31: =U31+W31 -> 2511 | AT31: =IF(AI31>0, ROUND(AS31/AI31,3),0) -> 0.478 | AU31: =IF($W31>0,IF(AT31>0.8999,"Study 1", "OK"),"OK") -> OK | AV31: =V31+W31 -> 0 | AW31: =IF(AK31>0, ROUND(AV31/AK31,3),0) -> #REF! | AX31: =IF(AND(V31=0, AV31>0), "DATA1", IF(OR(AV31>AL31,BI31>0), IF(Y31="CONC. (ART-PLAN)", "STUDY 1", "STUDY 2"), "OK")) -> #REF! | BA31: =IF(AG31>0, X31/AG31, 0) -> 0 | BB31: =IF(AM31>AF31,1,0) -> 1 | BC31: =SUMIF(#REF!,#REF!, BB20:BB333) -> #REF! | BD31: =IF(AP31>AH31,1,0) -> 1 | BE31: =SUMIF(#REF!,#REF!, BD20:BD333) -> #REF! | BF31: =IF(AS31>AJ31,1,0) -> 0 | BG31: =SUMIF(#REF!,#REF!, BF20:BF333) -> #REF! | BH31: =IF(AV31>AL31,1,0) -> #REF! | BI31: =SUMIF(B20:B333, B31, BH20:BH333) -> 0
A32: 10120 | C32: BROAD ST (US41/SR45) | D32: WISCON RD | E32: CORTEZ BLVD (SR50) | F32: 6D | H32: 6D | I32: Y | J32: N | N32: 32640 | O32: 34638 | P32: 36037 | R32: 0.09 | S32: 2938 | T32: 3117 | U32: 3243 | V32: =ROUND(R32*Q32,0) -> 0 | Y32: GEN. TABLES | Z32: ='[1]Tier 1'!V32 -> C | AE32: ='[1]Tier 1'!W32 -> 2090 | AG32: ='[1]Tier 1'!X32 -> 2090 | AI32: ='[1]Tier 1'!Y32 -> 2090 | AJ32: =AI32 * 0.9 -> 1881 | AK32: =VLOOKUP(A32,#REF!,-1,FALSE) -> #REF! | AL32: =AK32 * 0.9 -> #REF! | AM32: =S32+W32 -> 2938 | AN32: =IF(AE32>0, ROUND(AM32/AE32,3),0) -> 1.406 | AO32: =IF($W32>0,IF(AN32>0.8999,"Study 1", "OK"),"OK") -> OK | AP32: =T32+W32 -> 3117 | AQ32: =IF(AG32>0, ROUND(AP32/AG32,3),0) -> 1.491 | AR32: =IF($W32>0,IF(AQ32>0.8999,"Study 1", "OK"),"OK") -> OK | AS32: =U32+W32 -> 3243 | AT32: =IF(AI32>0, ROUND(AS32/AI32,3),0) -> 1.552 | AU32: =IF($W32>0,IF(AT32>0.8999,"Study 1", "OK"),"OK") -> OK | AV32: =V32+W32 -> 0 | AW32: =IF(AK32>0, ROUND(AV32/AK32,3),0) -> #REF! | AX32: =IF(AND(V32=0, AV32>0), "DATA1", IF(OR(AV32>AL32,BI32>0), IF(Y32="CONC. (ART-PLAN)", "STUDY 1", "STUDY 2"), "OK")) -> #REF! | BA32: =IF(AG32>0, X32/AG32, 0) -> 0 | BB32: =IF(AM32>AF32,1,0) -> 1 | BC32: =SUMIF(#REF!,#REF!, BB20:BB333) -> #REF! | BD32: =IF(AP32>AH32,1,0) -> 1 | BE32: =SUMIF(#REF!,#REF!, BD20:BD333) -> #REF! | BF32: =IF(AS32>AJ32,1,0) -> 1 | BG32: =SUMIF(#REF!,#REF!, BF20:BF333) -> #REF! | BH32: =IF(AV32>AL32,1,0) -> #REF! | BI32: =SUMIF(B20:B333, B32, BH20:BH333) -> 0
A33: 10130 | C33: BROAD ST (US41/SR45) | D33: CORTEZ BLVD (SR50) | E33: WINN DIXIE PLAZA | F33: 6D | H33: 6D | I33: Y | J33: N | N33: 32640 | O33: 34638 | P33: 36037 | R33: 0.09 | S33: 2938 | T33: 3117 | U33: 3243 | V33: =ROUND(R33*Q33,0) -> 0 | Y33: GEN. TABLES | Z33: ='[1]Tier 1'!V33 -> C | AE33: ='[1]Tier 1'!W33 -> 2090 | AG33: ='[1]Tier 1'!X33 -> 2090 | AI33: ='[1]Tier 1'!Y33 -> 2090 | AJ33: =AI33 * 0.9 -> 1881 | AK33: =VLOOKUP(A33,#REF!,-1,FALSE) -> #REF! | AL33: =AK33 * 0.9 -> #REF! | AM33: =S33+W33 -> 2938 | AN33: =IF(AE33>0, ROUND(AM33/AE33,3),0) -> 1.406 | AO33: =IF($W33>0,IF(AN33>0.8999,"Study 1", "OK"),"OK") -> OK | AP33: =T33+W33 -> 3117 | AQ33: =IF(AG33>0, ROUND(AP33/AG33,3),0) -> 1.491 | AR33: =IF($W33>0,IF(AQ33>0.8999,"Study 1", "OK"),"OK") -> OK | AS33: =U33+W33 -> 3243 | AT33: =IF(AI33>0, ROUND(AS33/AI33,3),0) -> 1.552 | AU33: =IF($W33>0,IF(AT33>0.8999,"Study 1", "OK"),"OK") -> OK | AV33: =V33+W33 -> 0 | AW33: =IF(AK33>0, ROUND(AV33/AK33,3),0) -> #REF! | AX33: =IF(AND(V33=0, AV33>0), "DATA1", IF(OR(AV33>AL33,BI33>0), IF(Y33="CONC. (ART-PLAN)", "STUDY 1", "STUDY 2"), "OK")) -> #REF! | BA33: =IF(AG33>0, X33/AG33, 0) -> 0 | BB33: =IF(AM33>AF33,1,0) -> 1 | BC33: =SUMIF(#REF!,#REF!, BB20:BB333) -> #REF! | BD33: =IF(AP33>AH33,1,0) -> 1 | BE33: =SUMIF(#REF!,#REF!, BD20:BD333) -> #REF! | BF33: =IF(AS33>AJ33,1,0) -> 1 | BG33: =SUMIF(#REF!,#REF!, BF20:BF333) -> #REF! | BH33: =IF(AV33>AL33,1,0) -> #REF! | BI33: =SUMIF(B20:B333, B33, BH20:BH333) -> 0
A34: 10140 | C34: BROAD ST (US41/SR45) | D34: WINN DIXIE PLAZA | E34: CANDLELIGHT BLVD | F34: 6D | H34: 6D | I34: Y | J34: N | N34: 25447 | O34: 26956 | P34: 27962 | R34: 0.09 | S34: 2290 | T34: 2426 | U34: 2517 | V34: =ROUND(R34*Q34,0) -> 0 | Y34: GEN. TABLES | Z34: ='[1]Tier 1'!V34 -> C | AE34: ='[1]Tier 1'!W34 -> 2090 | AG34: ='[1]Tier 1'!X34 -> 2090 | AI34: ='[1]Tier 1'!Y34 -> 2090 | AJ34: =AI34 * 0.9 -> 1881 | AK34: =VLOOKUP(A34,#REF!,-1,FALSE) -> #REF! | AL34: =AK34 * 0.9 -> #REF! | AM34: =S34+W34 -> 2290 | AN34: =IF(AE34>0, ROUND(AM34/AE34,3),0) -> 1.096 | AO34: =IF($W34>0,IF(AN34>0.8999,"Study 1", "OK"),"OK") -> OK | AP34: =T34+W34 -> 2426 | AQ34: =IF(AG34>0, ROUND(AP34/AG34,3),0) -> 1.161 | AR34: =IF($W34>0,IF(AQ34>0.8999,"Study 1", "OK"),"OK") -> OK | AS34: =U34+W34 -> 2517 | AT34: =IF(AI34>0, ROUND(AS34/AI34,3),0) -> 1.204 | AU34: =IF($W34>0,IF(AT34>0.8999,"Study 1", "OK"),"OK") -> OK | AV34: =V34+W34 -> 0 | AW34: =IF(AK34>0, ROUND(AV34/AK34,3),0) -> #REF! | AX34: =IF(AND(V34=0, AV34>0), "DATA1", IF(OR(AV34>AL34,BI34>0), IF(Y34="CONC. (ART-PLAN)", "STUDY 1", "STUDY 2"), "OK")) -> #REF! | BA34: =IF(AG34>0, X34/AG34, 0) -> 0 | BB34: =IF(AM34>AF34,1,0) -> 1 | BC34: =SUMIF(#REF!,#REF!, BB20:BB333) -> #REF! | BD34: =IF(AP34>AH34,1,0) -> 1 | BE34: =SUMIF(#REF!,#REF!, BD20:BD333) -> #REF! | BF34: =IF(AS34>AJ34,1,0) -> 1 | BG34: =SUMIF(#REF!,#REF!, BF20:BF333) -> #REF! | BH34: =IF(AV34>AL34,1,0) -> #REF! | BI34: =SUMIF(B20:B333, B34, BH20:BH333) -> 0
A35: 10150 | C35: BROAD ST (US41/SR45) | D35: CANDLELIGHT BLVD | E35: MLK BLVD | F35: 6D | H35: 2D | I35: Y | J35: N | N35: 25447 | O35: 26956 | P35: 27962 | R35: 0.09 | S35: 2290 | T35: 2426 | U35: 2517 | V35: =ROUND(R35*Q35,0) -> 0 | Y35: GEN. TABLES | Z35: ='[1]Tier 1'!V35 -> C | AE35: ='[1]Tier 1'!W35 -> 2090 | AG35: ='[1]Tier 1'!X35 -> 2090 | AI35: ='[1]Tier 1'!Y35 -> 2090 | AJ35: =AI35 * 0.9 -> 1881 | AK35: =VLOOKUP(A35,#REF!,-1,FALSE) -> #REF! | AL35: =AK35 * 0.9 -> #REF! | AM35: =S35+W35 -> 2290 | AN35: =IF(AE35>0, ROUND(AM35/AE35,3),0) -> 1.096 | AO35: =IF($W35>0,IF(AN35>0.8999,"Study 1", "OK"),"OK") -> OK | AP35: =T35+W35 -> 2426 | AQ35: =IF(AG35>0, ROUND(AP35/AG35,3),0) -> 1.161 | AR35: =IF($W35>0,IF(AQ35>0.8999,"Study 1", "OK"),"OK") -> OK | AS35: =U35+W35 -> 2517 | AT35: =IF(AI35>0, ROUND(AS35/AI35,3),0) -> 1.204 | AU35: =IF($W35>0,IF(AT35>0.8999,"Study 1", "OK"),"OK") -> OK | AV35: =V35+W35 -> 0 | AW35: =IF(AK35>0, ROUND(AV35/AK35,3),0) -> #REF! | AX35: =IF(AND(V35=0, AV35>0), "DATA1", IF(OR(AV35>AL35,BI35>0), IF(Y35="CONC. (ART-PLAN)", "STUDY 1", "STUDY 2"), "OK")) -> #REF! | BA35: =IF(AG35>0, X35/AG35, 0) -> 0 | BB35: =IF(AM35>AF35,1,0) -> 1 | BC35: =SUMIF(#REF!,#REF!, BB20:BB333) -> #REF! | BD35: =IF(AP35>AH35,1,0) -> 1 | BE35: =SUMIF(#REF!,#REF!, BD20:BD333) -> #REF! | BF35: =IF(AS35>AJ35,1,0) -> 1 | BG35: =SUMIF(#REF!,#REF!, BF20:BF333) -> #REF! | BH35: =IF(AV35>AL35,1,0) -> #REF! | BI35: =SUMIF(B20:B333, B35, BH20:BH333) -> 0
A36: 10160 | C36: BROAD ST (US41/SR45) | D36: MLK BLVD | E36: PONCE DE LEON BLVD (US98/SR700) | F36: 6D | H36: 2D | I36: Y | J36: N | N36: 25447 | O36: 26956 | P36: 27962 | R36: 0.09 | S36: 2290 | T36: 2426 | U36: 2517 | V36: =ROUND(R36*Q36,0) -> 0 | Y36: GEN. TABLES | Z36: ='[1]Tier 1'!V36 -> C | AE36: ='[1]Tier 1'!W36 -> 2090 | AG36: ='[1]Tier 1'!X36 -> 2090 | AI36: ='[1]Tier 1'!Y36 -> 2090 | AJ36: =AI36 * 0.9 -> 1881 | AK36: =VLOOKUP(A36,#REF!,-1,FALSE) -> #REF! | AL36: =AK36 * 0.9 -> #REF! | AM36: =S36+W36 -> 2290 | AN36: =IF(AE36>0, ROUND(AM36/AE36,3),0) -> 1.096 | AO36: =IF($W36>0,IF(AN36>0.8999,"Study 1", "OK"),"OK") -> OK | AP36: =T36+W36 -> 2426 | AQ36: =IF(AG36>0, ROUND(AP36/AG36,3),0) -> 1.161 | AR36: =IF($W36>0,IF(AQ36>0.8999,"Study 1", "OK"),"OK") -> OK | AS36: =U36+W36 -> 2517 | AT36: =IF(AI36>0, ROUND(AS36/AI36,3),0) -> 1.204 | AU36: =IF($W36>0,IF(AT36>0.8999,"Study 1", "OK"),"OK") -> OK | AV36: =V36+W36 -> 0 | AW36: =IF(AK36>0, ROUND(AV36/AK36,3),0) -> #REF! | AX36: =IF(AND(V36=0, AV36>0), "DATA1", IF(OR(AV36>AL36,BI36>0), IF(Y36="CONC. (ART-PLAN)", "STUDY 1", "STUDY 2"), "OK")) -> #REF! | BA36: =IF(AG36>0, X36/AG36, 0) -> 0 | BB36: =IF(AM36>AF36,1,0) -> 1 | BC36: =SUMIF(#REF!,#REF!, BB20:BB333) -> #REF! | BD36: =IF(AP36>AH36,1,0) -> 1 | BE36: =SUMIF(#REF!,#REF!, BD20:BD333) -> #REF! | BF36: =IF(AS36>AJ36,1,0) -> 1 | BG36: =SUMIF(#REF!,#REF!, BF20:BF333) -> #REF! | BH36: =IF(AV36>AL36,1,0) -> #REF! | BI36: =SUMIF(B20:B333, B36, BH20:BH333) -> 0
A37: 10170 | C37: BROAD ST (US41/SR45) | D37: PONCE DE LEON BLVD (US98/SR700) | E37: BENTON AVE | F37: 2D | H37: 2D | I37: Y | J37: N | N37: 25447 | O37: 26956 | P37: 27962 | R37: 0.09 | S37: 2290 | T37: 2426 | U37: 2517 | V37: =ROUND(R37*Q37,0) -> 0 | Y37: GEN. TABLES | Z37: ='[1]Tier 1'!V37 -> C | AE37: ='[1]Tier 1'!W37 -> 2090 | AG37: ='[1]Tier 1'!X37 -> 2090 | AI37: ='[1]Tier 1'!Y37 -> 2090 | AJ37: =AI37 * 0.9 -> 1881 | AK37: =VLOOKUP(A37,#REF!,-1,FALSE) -> #REF! | AL37: =AK37 * 0.9 -> #REF! | AM37: =S37+W37 -> 2290 | AN37: =IF(AE37>0, ROUND(AM37/AE37,3),0) -> 1.096 | AO37: =IF($W37>0,IF(AN37>0.8999,"Study 1", "OK"),"OK") -> OK | AP37: =T37+W37 -> 2426 | AQ37: =IF(AG37>0, ROUND(AP37/AG37,3),0) -> 1.161 | AR37: =IF($W37>0,IF(AQ37>0.8999,"Study 1", "OK"),"OK") -> OK | AS37: =U37+W37 -> 2517 | AT37: =IF(AI37>0, ROUND(AS37/AI37,3),0) -> 1.204 | AU37: =IF($W37>0,IF(AT37>0.8999,"Study 1", "OK"),"OK") -> OK | AV37: =V37+W37 -> 0 | AW37: =IF(AK37>0, ROUND(AV37/AK37,3),0) -> #REF! | AX37: =IF(AND(V37=0, AV37>0), "DATA1", IF(OR(AV37>AL37,BI37>0), IF(Y37="CONC. (ART-PLAN)", "STUDY 1", "STUDY 2"), "OK")) -> #REF! | BA37: =IF(AG37>0, X37/AG37, 0) -> 0 | BB37: =IF(AM37>AF37,1,0) -> 1 | BC37: =SUMIF(#REF!,#REF!, BB20:BB333) -> #REF! | BD37: =IF(AP37>AH37,1,0) -> 1 | BE37: =SUMIF(#REF!,#REF!, BD20:BD333) -> #REF! | BF37: =IF(AS37>AJ37,1,0) -> 1 | BG37: =SUMIF(#REF!,#REF!, BF20:BF333) -> #REF! | BH37: =IF(AV37>AL37,1,0) -> #REF! | BI37: =SUMIF(B20:B333, B37, BH20:BH333) -> 0
A38: 10180 | C38: BROAD ST (US41/SR45) | D38: BENTON AVE | E38: OLD HOSPITAL DR | F38: 2D | H38: 6D | I38: Y | J38: N | N38: 12240 | O38: 12989 | P38: 13514 | R38: 0.09 | S38: 1102 | T38: 1169 | U38: 1216 | V38: =ROUND(R38*Q38,0) -> 0 | Y38: GEN. TABLES | Z38: ='[1]Tier 1'!V38 -> C | AE38: ='[1]Tier 1'!W38 -> 2090 | AG38: ='[1]Tier 1'!X38 -> 2090 | AI38: ='[1]Tier 1'!Y38 -> 2090 | AJ38: =AI38 * 0.9 -> 1881 | AK38: =VLOOKUP(A38,#REF!,-1,FALSE) -> #REF! | AL38: =AK38 * 0.9 -> #REF! | AM38: =S38+W38 -> 1102 | AN38: =IF(AE38>0, ROUND(AM38/AE38,3),0) -> 0.527 | AO38: =IF($W38>0,IF(AN38>0.8999,"Study 1", "OK"),"OK") -> OK | AP38: =T38+W38 -> 1169 | AQ38: =IF(AG38>0, ROUND(AP38/AG38,3),0) -> 0.559 | AR38: =IF($W38>0,IF(AQ38>0.8999,"Study 1", "OK"),"OK") -> OK | AS38: =U38+W38 -> 1216 | AT38: =IF(AI38>0, ROUND(AS38/AI38,3),0) -> 0.582 | AU38: =IF($W38>0,IF(AT38>0.8999,"Study 1", "OK"),"OK") -> OK | AV38: =V38+W38 -> 0 | AW38: =IF(AK38>0, ROUND(AV38/AK38,3),0) -> #REF! | AX38: =IF(AND(V38=0, AV38>0), "DATA1", IF(OR(AV38>AL38,BI38>0), IF(Y38="CONC. (ART-PLAN)", "STUDY 1", "STUDY 2"), "OK")) -> #REF! | BA38: =IF(AG38>0, X38/AG38, 0) -> 0 | BB38: =IF(AM38>AF38,1,0) -> 1 | BC38: =SUMIF(#REF!,#REF!, BB20:BB333) -> #REF! | BD38: =IF(AP38>AH38,1,0) -> 1 | BE38: =SUMIF(#REF!,#REF!, BD20:BD333) -> #REF! | BF38: =IF(AS38>AJ38,1,0) -> 0 | BG38: =SUMIF(#REF!,#REF!, BF20:BF333) -> #REF! | BH38: =IF(AV38>AL38,1,0) -> #REF! | BI38: =SUMIF(B20:B333, B38, BH20:BH333) -> 0
A39: 10190 | C39: BROAD ST (US41/SR45) | D39: OLD HOSPITAL DR | E39: MILDRED AVE | F39: 2D | H39: 2U | I39: Y | J39: N | N39: 25447 | O39: 26956 | P39: 27962 | R39: 0.09 | S39: 2290 | T39: 2426 | U39: 2517 | V39: =ROUND(R39*Q39,0) -> 0 | Y39: GEN. TABLES | Z39: ='[1]Tier 1'!V39 -> C | AE39: ='[1]Tier 1'!W39 -> 2090 | AG39: ='[1]Tier 1'!X39 -> 2090 | AI39: ='[1]Tier 1'!Y39 -> 2090 | AJ39: =AI39 * 0.9 -> 1881 | AK39: =VLOOKUP(A39,#REF!,-1,FALSE) -> #REF! | AL39: =AK39 * 0.9 -> #REF! | AM39: =S39+W39 -> 2290 | AN39: =IF(AE39>0, ROUND(AM39/AE39,3),0) -> 1.096 | AO39: =IF($W39>0,IF(AN39>0.8999,"Study 1", "OK"),"OK") -> OK | AP39: =T39+W39 -> 2426 | AQ39: =IF(AG39>0, ROUND(AP39/AG39,3),0) -> 1.161 | AR39: =IF($W39>0,IF(AQ39>0.8999,"Study 1", "OK"),"OK") -> OK | AS39: =U39+W39 -> 2517 | AT39: =IF(AI39>0, ROUND(AS39/AI39,3),0) -> 1.204 | AU39: =IF($W39>0,IF(AT39>0.8999,"Study 1", "OK"),"OK") -> OK | AV39: =V39+W39 -> 0 | AW39: =IF(AK39>0, ROUND(AV39/AK39,3),0) -> #REF! | AX39: =IF(AND(V39=0, AV39>0), "DATA1", IF(OR(AV39>AL39,BI39>0), IF(Y39="CONC. (ART-PLAN)", "STUDY 1", "STUDY 2"), "OK")) -> #REF! | BA39: =IF(AG39>0, X39/AG39, 0) -> 0 | BB39: =IF(AM39>AF39,1,0) -> 1 | BC39: =SUMIF(#REF!,#REF!, BB20:BB333) -> #REF! | BD39: =IF(AP39>AH39,1,0) -> 1 | BE39: =SUMIF(#REF!,#REF!, BD20:BD333) -> #REF! | BF39: =IF(AS39>AJ39,1,0) -> 1 | BG39: =SUMIF(#REF!,#REF!, BF20:BF333) -> #REF! | BH39: =IF(AV39>AL39,1,0) -> #REF! | BI39: =SUMIF(B20:B333, B39, BH20:BH333) -> 0
A40: 10200 | C40: BROAD ST (US41/SR45) | D40: MILDRED AVE | E40: MAIN ST (CR445) | F40: 4D | H40: 2U | I40: Y | J40: N | N40: 10200 | O40: 10824 | P40: 10418 | R40: 0.09 | S40: 918 | T40: 974 | U40: 938 | V40: =ROUND(R40*Q40,0) -> 0 | Y40: GEN. TABLES | Z40: ='[1]Tier 1'!V40 -> C | AE40: ='[1]Tier 1'!W40 -> 786 | AG40: ='[1]Tier 1'!X40 -> 786 | AI40: ='[1]Tier 1'!Y40 -> 786 | AJ40: =AI40 * 0.9 -> 707.4 | AK40: =VLOOKUP(A40,#REF!,-1,FALSE) -> #REF! | AL40: =AK40 * 0.9 -> #REF! | AM40: =S40+W40 -> 918 | AN40: =IF(AE40>0, ROUND(AM40/AE40,3),0) -> 1.168 | AO40: =IF($W40>0,IF(AN40>0.8999,"Study 1", "OK"),"OK") -> OK | AP40: =T40+W40 -> 974 | AQ40: =IF(AG40>0, ROUND(AP40/AG40,3),0) -> 1.239 | AR40: =IF($W40>0,IF(AQ40>0.8999,"Study 1", "OK"),"OK") -> OK | AS40: =U40+W40 -> 938 | AT40: =IF(AI40>0, ROUND(AS40/AI40,3),0) -> 1.193 | AU40: =IF($W40>0,IF(AT40>0.8999,"Study 1", "OK"),"OK") -> OK | AV40: =V40+W40 -> 0 | AW40: =IF(AK40>0, ROUND(AV40/AK40,3),0) -> #REF! | AX40: =IF(AND(V40=0, AV40>0), "DATA1", IF(OR(AV40>AL40,BI40>0), IF(Y40="CONC. (ART-PLAN)", "STUDY 1", "STUDY 2"), "OK")) -> #REF! | BA40: =IF(AG40>0, X40/AG40, 0) -> 0 | BB40: =IF(AM40>AF40,1,0) -> 1 | BC40: =SUMIF(#REF!,#REF!, BB20:BB333) -> #REF! | BD40: =IF(AP40>AH40,1,0) -> 1 | BE40: =SUMIF(#REF!,#REF!, BD20:BD333) -> #REF! | BF40: =IF(AS40>AJ40,1,0) -> 1 | BG40: =SUMIF(#REF!,#REF!, BF20:BF333) -> #REF! | BH40: =IF(AV40>AL40,1,0) -> #REF! | BI40: =SUMIF(B20:B333, B40, BH20:BH333) -> 0
A41: 10210 | C41: BROAD ST (US41/SR45) | D41: MAIN ST (CR445) | E41: JEFFERSON ST (SR50) | F41: 2U | H41: 2U | I41: Y | J41: N | N41: 9078 | O41: 9108 | P41: 9416 | R41: 0.09 | S41: 817 | T41: 820 | U41: 847 | V41: =ROUND(R41*Q41,0) -> 0 | Y41: GEN. TABLES | Z41: ='[1]Tier 1'!V41 -> C | AE41: ='[1]Tier 1'!W41 -> 786 | AG41: ='[1]Tier 1'!X41 -> 786 | AI41: ='[1]Tier 1'!Y41 -> 786 | AJ41: =AI41 * 0.9 -> 707.4 | AK41: =VLOOKUP(A41,#REF!,-1,FALSE) -> #REF! | AL41: =AK41 * 0.9 -> #REF! | AM41: =S41+W41 -> 817 | AN41: =IF(AE41>0, ROUND(AM41/AE41,3),0) -> 1.039 | AO41: =IF($W41>0,IF(AN41>0.8999,"Study 1", "OK"),"OK") -> OK | AP41: =T41+W41 -> 820 | AQ41: =IF(AG41>0, ROUND(AP41/AG41,3),0) -> 1.043 | AR41: =IF($W41>0,IF(AQ41>0.8999,"Study 1", "OK"),"OK") -> OK | AS41: =U41+W41 -> 847 | AT41: =IF(AI41>0, ROUND(AS41/AI41,3),0) -> 1.078 | AU41: =IF($W41>0,IF(AT41>0.8999,"Study 1", "OK"),"OK") -> OK | AV41: =V41+W41 -> 0 | AW41: =IF(AK41>0, ROUND(AV41/AK41,3),0) -> #REF! | AX41: =IF(AND(V41=0, AV41>0), "DATA1", IF(OR(AV41>AL41,BI41>0), IF(Y41="CONC. (ART-PLAN)", "STUDY 1", "STUDY 2"), "OK")) -> #REF! | BA41: =IF(AG41>0, X41/AG41, 0) -> 0 | BB41: =IF(AM41>AF41,1,0) -> 1 | BC41: =SUMIF(#REF!,#REF!, BB20:BB333) -> #REF! | BD41: =IF(AP41>AH41,1,0) -> 1 | BE41: =SUMIF(#REF!,#REF!, BD20:BD333) -> #REF! | BF41: =IF(AS41>AJ41,1,0) -> 1 | BG41: =SUMIF(#REF!,#REF!, BF20:BF333) -> #REF! | BH41: =IF(AV41>AL41,1,0) -> #REF! | BI41: =SUMIF(B20:B333, B41, BH20:BH333) -> 0
A42: 10220 | C42: BROAD ST (US41/SR45) | D42: JEFFERSON ST (SR50) | E42: MONDON HILL RD | F42: 2U | H42: 2U | I42: Y | J42: N | N42: 10200 | O42: 10824 | P42: 11262 | R42: 0.09 | S42: 918 | T42: 974 | U42: 1014 | V42: =ROUND(R42*Q42,0) -> 0 | Y42: GEN. TABLES | Z42: ='[1]Tier 1'!V42 -> C | AE42: ='[1]Tier 1'!W42 -> 1620 | AG42: ='[1]Tier 1'!X42 -> 1620 | AI42: ='[1]Tier 1'!Y42 -> 1620 | AJ42: =AI42 * 0.9 -> 1458 | AK42: =VLOOKUP(A42,#REF!,-1,FALSE) -> #REF! | AL42: =AK42 * 0.9 -> #REF! | AM42: =S42+W42 -> 918 | AN42: =IF(AE42>0, ROUND(AM42/AE42,3),0) -> 0.567 | AO42: =IF($W42>0,IF(AN42>0.8999,"Study 1", "OK"),"OK") -> OK | AP42: =T42+W42 -> 974 | AQ42: =IF(AG42>0, ROUND(AP42/AG42,3),0) -> 0.601 | AR42: =IF($W42>0,IF(AQ42>0.8999,"Study 1", "OK"),"OK") -> OK | AS42: =U42+W42 -> 1014 | AT42: =IF(AI42>0, ROUND(AS42/AI42,3),0) -> 0.626 | AU42: =IF($W42>0,IF(AT42>0.8999,"Study 1", "OK"),"OK") -> OK | AV42: =V42+W42 -> 0 | AW42: =IF(AK42>0, ROUND(AV42/AK42,3),0) -> #REF! | AX42: =IF(AND(V42=0, AV42>0), "DATA1", IF(OR(AV42>AL42,BI42>0), IF(Y42="CONC. (ART-PLAN)", "STUDY 1", "STUDY 2"), "OK")) -> #REF! | BA42: =IF(AG42>0, X42/AG42, 0) -> 0 | BB42: =IF(AM42>AF42,1,0) -> 1 | BC42: =SUMIF(#REF!,#REF!, BB20:BB333) -> #REF! | BD42: =IF(AP42>AH42,1,0) -> 1 | BE42: =SUMIF(#REF!,#REF!, BD20:BD333) -> #REF! | BF42: =IF(AS42>AJ42,1,0) -> 0 | BG42: =SUMIF(#REF!,#REF!, BF20:BF333) -> #REF! | BH42: =IF(AV42>AL42,1,0) -> #REF! | BI42: =SUMIF(B20:B333, B42, BH20:BH333) -> 0
A43: 10230.1 | C43: BROAD ST (US41/SR45) | D43: MONDON HILL RD | E43: N OF OAK ST | F43: 2U | H43: 2U | I43: Y | J43: N | N43: 9959 | O43: 10569 | P43: 10996 | R43: 0.09 | S43: 896 | T43: 951 | U43: 990 | V43: =ROUND(R43*Q43,0) -> 0 | Y43: GEN. TABLES | Z43: ='[1]Tier 1'!V43 -> C | AE43: ='[1]Tier 1'!W43 -> 1620 | AG43: ='[1]Tier 1'!X43 -> 1620 | AI43: ='[1]Tier 1'!Y43 -> 1620 | AJ43: =AI43 * 0.9 -> 1458 | AK43: =VLOOKUP(A43,#REF!,-1,FALSE) -> #REF! | AL43: =AK43 * 0.9 -> #REF! | AM43: =S43+W43 -> 896 | AN43: =IF(AE43>0, ROUND(AM43/AE43,3),0) -> 0.553 | AO43: =IF($W43>0,IF(AN43>0.8999,"Study 1", "OK"),"OK") -> OK | AP43: =T43+W43 -> 951 | AQ43: =IF(AG43>0, ROUND(AP43/AG43,3),0) -> 0.587 | AR43: =IF($W43>0,IF(AQ43>0.8999,"Study 1", "OK"),"OK") -> OK | AS43: =U43+W43 -> 990 | AT43: =IF(AI43>0, ROUND(AS43/AI43,3),0) -> 0.611 | AU43: =IF($W43>0,IF(AT43>0.8999,"Study 1", "OK"),"OK") -> OK | AV43: =V43+W43 -> 0 | AW43: =IF(AK43>0, ROUND(AV43/AK43,3),0) -> #REF! | AX43: =IF(AND(V43=0, AV43>0), "DATA1", IF(OR(AV43>AL43,BI43>0), IF(Y43="CONC. (ART-PLAN)", "STUDY 1", "STUDY 2"), "OK")) -> #REF! | BA43: =IF(AG43>0, X43/AG43, 0) -> 0 | BB43: =IF(AM43>AF43,1,0) -> 1 | BC43: =SUMIF(#REF!,#REF!, BB20:BB333) -> #REF! | BD43: =IF(AP43>AH43,1,0) -> 1 | BE43: =SUMIF(#REF!,#REF!, BD20:BD333) -> #REF! | BF43: =IF(AS43>AJ43,1,0) -> 0 | BG43: =SUMIF(#REF!,#REF!, BF20:BF333) -> #REF! | BH43: =IF(AV43>AL43,1,0) -> #REF! | BI43: =SUMIF(B20:B333, B43, BH20:BH333) -> 0
A44: 10230.2 | C44: BROAD ST (US41/SR45) | D44: N OF OAK ST | E44: CROOM RD | F44: 2U | H44: 2U | I44: Y | J44: N | N44: 9959 | O44: 10569 | P44: 10996 | R44: 0.09 | S44: 896 | T44: 951 | U44: 990 | V44: =ROUND(R44*Q44,0) -> 0 | Y44: GEN. TABLES | Z44: ='[1]Tier 1'!V44 -> C | AE44: ='[1]Tier 1'!W44 -> 1620 | AG44: ='[1]Tier 1'!X44 -> 1620 | AI44: ='[1]Tier 1'!Y44 -> 1620 | AJ44: =AI44 * 0.9 -> 1458 | AK44: =VLOOKUP(A44,#REF!,-1,FALSE) -> #REF! | AL44: =AK44 * 0.9 -> #REF! | AM44: =S44+W44 -> 896 | AN44: =IF(AE44>0, ROUND(AM44/AE44,3),0) -> 0.553 | AO44: =IF($W44>0,IF(AN44>0.8999,"Study 1", "OK"),"OK") -> OK | AP44: =T44+W44 -> 951 | AQ44: =IF(AG44>0, ROUND(AP44/AG44,3),0) -> 0.587 | AR44: =IF($W44>0,IF(AQ44>0.8999,"Study 1", "OK"),"OK") -> OK | AS44: =U44+W44 -> 990 | AT44: =IF(AI44>0, ROUND(AS44/AI44,3),0) -> 0.611 | AU44: =IF($W44>0,IF(AT44>0.8999,"Study 1", "OK"),"OK") -> OK | AV44: =V44+W44 -> 0 | AW44: =IF(AK44>0, ROUND(AV44/AK44,3),0) -> #REF! | AX44: =IF(AND(V44=0, AV44>0), "DATA1", IF(OR(AV44>AL44,BI44>0), IF(Y44="CONC. (ART-PLAN)", "STUDY 1", "STUDY 2"), "OK")) -> #REF! | BA44: =IF(AG44>0, X44/AG44, 0) -> 0 | BB44: =IF(AM44>AF44,1,0) -> 1 | BC44: =SUMIF(#REF!,#REF!, BB20:BB333) -> #REF! | BD44: =IF(AP44>AH44,1,0) -> 1 | BE44: =SUMIF(#REF!,#REF!, BD20:BD333) -> #REF! | BF44: =IF(AS44>AJ44,1,0) -> 0 | BG44: =SUMIF(#REF!,#REF!, BF20:BF333) -> #REF! | BH44: =IF(AV44>AL44,1,0) -> #REF! | BI44: =SUMIF(B20:B333, B44, BH20:BH333) -> 0
A45: 10240 | C45: BROAD ST (US41/SR45) | D45: CROOM RD | E45: CHATFIELD DR | F45: 2U | H45: 2U | I45: Y | J45: N | N45: 8058 | O45: 8373 | P45: 8755 | R45: 0.09 | S45: 725 | T45: 754 | U45: 788 | V45: =ROUND(R45*Q45,0) -> 0 | Y45: GEN. TABLES | Z45: ='[1]Tier 1'!V45 -> C | AE45: ='[1]Tier 1'!W45 -> 1620 | AG45: ='[1]Tier 1'!X45 -> 1620 | AI45: ='[1]Tier 1'!Y45 -> 1620 | AJ45: =AI45 * 0.9 -> 1458 | AK45: =VLOOKUP(A45,#REF!,-1,FALSE) -> #REF! | AL45: =AK45 * 0.9 -> #REF! | AM45: =S45+W45 -> 725 | AN45: =IF(AE45>0, ROUND(AM45/AE45,3),0) -> 0.448 | AO45: =IF($W45>0,IF(AN45>0.8999,"Study 1", "OK"),"OK") -> OK | AP45: =T45+W45 -> 754 | AQ45: =IF(AG45>0, ROUND(AP45/AG45,3),0) -> 0.465 | AR45: =IF($W45>0,IF(AQ45>0.8999,"Study 1", "OK"),"OK") -> OK | AS45: =U45+W45 -> 788 | AT45: =IF(AI45>0, ROUND(AS45/AI45,3),0) -> 0.486 | AU45: =IF($W45>0,IF(AT45>0.8999,"Study 1", "OK"),"OK") -> OK | AV45: =V45+W45 -> 0 | AW45: =IF(AK45>0, ROUND(AV45/AK45,3),0) -> #REF! | AX45: =IF(AND(V45=0, AV45>0), "DATA1", IF(OR(AV45>AL45,BI45>0), IF(Y45="CONC. (ART-PLAN)", "STUDY 1", "STUDY 2"), "OK")) -> #REF! | BA45: =IF(AG45>0, X45/AG45, 0) -> 0 | BB45: =IF(AM45>AF45,1,0) -> 1 | BC45: =SUMIF(#REF!,#REF!, BB20:BB333) -> #REF! | BD45: =IF(AP45>AH45,1,0) -> 1 | BE45: =SUMIF(#REF!,#REF!, BD20:BD333) -> #REF! | BF45: =IF(AS45>AJ45,1,0) -> 0 | BG45: =SUMIF(#REF!,#REF!, BF20:BF333) -> #REF! | BH45: =IF(AV45>AL45,1,0) -> #REF! | BI45: =SUMIF(B20:B333, B45, BH20:BH333) -> 0
A46: 10250.1 | C46: BROAD ST (US41/SR45) | D46: CHATFIELD DR | E46: YONTZ RD | F46: 2U | H46: 2U | I46: Y | J46: N | N46: 8058 | O46: 8373 | P46: 8755 | R46: 0.09 | S46: 725 | T46: 754 | U46: 788 | V46: =ROUND(R46*Q46,0) -> 0 | Y46: GEN. TABLES | Z46: ='[1]Tier 1'!V46 -> C | AE46: ='[1]Tier 1'!W46 -> 1620 | AG46: ='[1]Tier 1'!X46 -> 1620 | AI46: ='[1]Tier 1'!Y46 -> 1620 | AJ46: =AI46 * 0.9 -> 1458 | AK46: =VLOOKUP(A46,#REF!,-1,FALSE) -> #REF! | AL46: =AK46 * 0.9 -> #REF! | AM46: =S46+W46 -> 725 | AN46: =IF(AE46>0, ROUND(AM46/AE46,3),0) -> 0.448 | AO46: =IF($W46>0,IF(AN46>0.8999,"Study 1", "OK"),"OK") -> OK | AP46: =T46+W46 -> 754 | AQ46: =IF(AG46>0, ROUND(AP46/AG46,3),0) -> 0.465 | AR46: =IF($W46>0,IF(AQ46>0.8999,"Study 1", "OK"),"OK") -> OK | AS46: =U46+W46 -> 788 | AT46: =IF(AI46>0, ROUND(AS46/AI46,3),0) -> 0.486 | AU46: =IF($W46>0,IF(AT46>0.8999,"Study 1", "OK"),"OK") -> OK | AV46: =V46+W46 -> 0 | AW46: =IF(AK46>0, ROUND(AV46/AK46,3),0) -> #REF! | AX46: =IF(AND(V46=0, AV46>0), "DATA1", IF(OR(AV46>AL46,BI46>0), IF(Y46="CONC. (ART-PLAN)", "STUDY 1", "STUDY 2"), "OK")) -> #REF! | BA46: =IF(AG46>0, X46/AG46, 0) -> 0 | BB46: =IF(AM46>AF46,1,0) -> 1 | BC46: =SUMIF(#REF!,#REF!, BB20:BB333) -> #REF! | BD46: =IF(AP46>AH46,1,0) -> 1 | BE46: =SUMIF(#REF!,#REF!, BD20:BD333) -> #REF! | BF46: =IF(AS46>AJ46,1,0) -> 0 | BG46: =SUMIF(#REF!,#REF!, BF20:BF333) -> #REF! | BH46: =IF(AV46>AL46,1,0) -> #REF! | BI46: =SUMIF(B20:B333, B46, BH20:BH333) -> 0
A47: 10250.2 | C47: BROAD ST (US41/SR45) | D47: YONTZ RD | E47: HOWELL AVE | F47: 2U | H47: 2U | I47: Y | J47: N | N47: 8058 | O47: 8373 | P47: 8755 | R47: 0.09 | S47: 725 | T47: 754 | U47: 788 | V47: =ROUND(R47*Q47,0) -> 0 | Y47: GEN. TABLES | Z47: ='[1]Tier 1'!V47 -> C | AE47: ='[1]Tier 1'!W47 -> 1620 | AG47: ='[1]Tier 1'!X47 -> 1620 | AI47: ='[1]Tier 1'!Y47 -> 1620 | AJ47: =AI47 * 0.9 -> 1458 | AK47: =VLOOKUP(A47,#REF!,-1,FALSE) -> #REF! | AL47: =AK47 * 0.9 -> #REF! | AM47: =S47+W47 -> 725 | AN47: =IF(AE47>0, ROUND(AM47/AE47,3),0) -> 0.448 | AO47: =IF($W47>0,IF(AN47>0.8999,"Study 1", "OK"),"OK") -> OK | AP47: =T47+W47 -> 754 | AQ47: =IF(AG47>0, ROUND(AP47/AG47,3),0) -> 0.465 | AR47: =IF($W47>0,IF(AQ47>0.8999,"Study 1", "OK"),"OK") -> OK | AS47: =U47+W47 -> 788 | AT47: =IF(AI47>0, ROUND(AS47/AI47,3),0) -> 0.486 | AU47: =IF($W47>0,IF(AT47>0.8999,"Study 1", "OK"),"OK") -> OK | AV47: =V47+W47 -> 0 | AW47: =IF(AK47>0, ROUND(AV47/AK47,3),0) -> #REF! | AX47: =IF(AND(V47=0, AV47>0), "DATA1", IF(OR(AV47>AL47,BI47>0), IF(Y47="CONC. (ART-PLAN)", "STUDY 1", "STUDY 2"), "OK")) -> #REF! | BA47: =IF(AG47>0, X47/AG47, 0) -> 0 | BB47: =IF(AM47>AF47,1,0) -> 1 | BC47: =SUMIF(#REF!,#REF!, BB20:BB333) -> #REF! | BD47: =IF(AP47>AH47,1,0) -> 1 | BE47: =SUMIF(#REF!,#REF!, BD20:BD333) -> #REF! | BF47: =IF(AS47>AJ47,1,0) -> 0 | BG47: =SUMIF(#REF!,#REF!, BF20:BF333) -> #REF! | BH47: =IF(AV47>AL47,1,0) -> #REF! | BI47: =SUMIF(B20:B333, B47, BH20:BH333) -> 0
A48: 10260.3 | C48: BROAD ST (US41/SR45) | D48: HOWELL AVE | E48: URBAN BOUNDARY | F48: 2U | H48: 2U | I48: Y | J48: N | N48: 1256 | O48: 1376 | P48: 1456 | R48: 0.09 | S48: 113 | T48: 124 | U48: 131 | V48: =ROUND(R48*Q48,0) -> 0 | Y48: GEN. TABLES | Z48: ='[1]Tier 1'!V48 -> C | AE48: ='[1]Tier 1'!W48 -> 1620 | AG48: ='[1]Tier 1'!X48 -> 1620 | AI48: ='[1]Tier 1'!Y48 -> 1620 | AJ48: =AI48 * 0.9 -> 1458 | AK48: =VLOOKUP(A48,#REF!,-1,FALSE) -> #REF! | AL48: =AK48 * 0.9 -> #REF! | AM48: =S48+W48 -> 113 | AN48: =IF(AE48>0, ROUND(AM48/AE48,3),0) -> 0.07 | AO48: =IF($W48>0,IF(AN48>0.8999,"Study 1", "OK"),"OK") -> OK | AP48: =T48+W48 -> 124 | AQ48: =IF(AG48>0, ROUND(AP48/AG48,3),0) -> 0.077 | AR48: =IF($W48>0,IF(AQ48>0.8999,"Study 1", "OK"),"OK") -> OK | AS48: =U48+W48 -> 131 | AT48: =IF(AI48>0, ROUND(AS48/AI48,3),0) -> 0.081 | AU48: =IF($W48>0,IF(AT48>0.8999,"Study 1", "OK"),"OK") -> OK | AV48: =V48+W48 -> 0 | AW48: =IF(AK48>0, ROUND(AV48/AK48,3),0) -> #REF! | AX48: =IF(AND(V48=0, AV48>0), "DATA1", IF(OR(AV48>AL48,BI48>0), IF(Y48="CONC. (ART-PLAN)", "STUDY 1", "STUDY 2"), "OK")) -> #REF! | BA48: =IF(AG48>0, X48/AG48, 0) -> 0 | BB48: =IF(AM48>AF48,1,0) -> 1 | BC48: =SUMIF(#REF!,#REF!, BB20:BB333) -> #REF! | BD48: =IF(AP48>AH48,1,0) -> 1 | BE48: =SUMIF(#REF!,#REF!, BD20:BD333) -> #REF! | BF48: =IF(AS48>AJ48,1,0) -> 0 | BG48: =SUMIF(#REF!,#REF!, BF20:BF333) -> #REF! | BH48: =IF(AV48>AL48,1,0) -> #REF! | BI48: =SUMIF(B20:B333, B48, BH20:BH333) -> 0
A49: 10260.4 | C49: BROAD ST (US41/SR45) | D49: URBAN BOUNDARY | E49: SNOW MEMORIAL HWY | F49: 2U | H49: 2U | I49: Y | J49: N | N49: 11730 | O49: 11964 | P49: 12353 | R49: 0.09 | S49: 1056 | T49: 1077 | U49: 1112 | V49: =ROUND(R49*Q49,0) -> 0 | Y49: GEN. TABLES | Z49: ='[1]Tier 1'!V49 -> C | AE49: ='[1]Tier 1'!W49 -> 1560 | AG49: ='[1]Tier 1'!X49 -> 1560 | AI49: ='[1]Tier 1'!Y49 -> 1560 | AJ49: =AI49 * 0.9 -> 1404 | AK49: =VLOOKUP(A49,#REF!,-1,FALSE) -> #REF! | AL49: =AK49 * 0.9 -> #REF! | AM49: =S49+W49 -> 1056 | AN49: =IF(AE49>0, ROUND(AM49/AE49,3),0) -> 0.677 | AO49: =IF($W49>0,IF(AN49>0.8999,"Study 1", "OK"),"OK") -> OK | AP49: =T49+W49 -> 1077 | AQ49: =IF(AG49>0, ROUND(AP49/AG49,3),0) -> 0.69 | AR49: =IF($W49>0,IF(AQ49>0.8999,"Study 1", "OK"),"OK") -> OK | AS49: =U49+W49 -> 1112 | AT49: =IF(AI49>0, ROUND(AS49/AI49,3),0) -> 0.713 | AU49: =IF($W49>0,IF(AT49>0.8999,"Study 1", "OK"),"OK") -> OK | AV49: =V49+W49 -> 0 | AW49: =IF(AK49>0, ROUND(AV49/AK49,3),0) -> #REF! | AX49: =IF(AND(V49=0, AV49>0), "DATA1", IF(OR(AV49>AL49,BI49>0), IF(Y49="CONC. (ART-PLAN)", "STUDY 1", "STUDY 2"), "OK")) -> #REF! | BA49: =IF(AG49>0, X49/AG49, 0) -> 0 | BB49: =IF(AM49>AF49,1,0) -> 1 | BC49: =SUMIF(#REF!,#REF!, BB20:BB333) -> #REF! | BD49: =IF(AP49>AH49,1,0) -> 1 | BE49: =SUMIF(#REF!,#REF!, BD20:BD333) -> #REF! | BF49: =IF(AS49>AJ49,1,0) -> 0 | BG49: =SUMIF(#REF!,#REF!, BF20:BF333) -> #REF! | BH49: =IF(AV49>AL49,1,0) -> #REF! | BI49: =SUMIF(B20:B333, B49, BH20:BH333) -> 0
...

Sheet Input
L6: Exiting | O6: Improved | R6: =$AA$2&" Existing Conditions" -> Existing Conditions | AJ6: Daily/2way/Directional per Agency
B7: Seg | C7: Segment Information | F7: Exist | G7: Imp | H7: LOS | I7: Functonal | J7: Facility | K7: Context | L7: Daily | M7: 2-Way | N7: Dir | O7: Daily | P7: Peak | Q7: Dir | R7: Daily | U7: AM 2-Way | X7: PM 2-Way | AA7: AM Directional | AE7: PM Directional | AI7: GR | AJ7: Adjusted Service Volumes
B8: ID | C8: Roadway | D8: From | E8: To | F8: Lns | G8: Lns | H8: Std | I8: Classification | J8: Type | K8: Classification | L8: Cap | M8: Cap | N8: Cap | O8: Cap | P8: Cap | Q8: Cap | R8: Volume | S8: V/C | T8: LOS | U8: Vol | V8: V/C | W8: LOS | X8: Vol | Y8: V/C | Z8: LOS | AA8: NB/EB | AB8: SB/WB | AC8: V/C | AD8: LOS | AE8: NB/EB | AF8: SB/WB | AG8: V/C | AH8: LOS | AJ8: B | AK8: C | AL8: D | AM8: E
B9: =Sheet1!A20 -> 10810 | C9: =Sheet1!C20 -> TREIMAN BLVD (US301/SR35) | D9: =Sheet1!D20 -> PASCO COUNTY LINE | E9: =Sheet1!E20 -> CORTEZ BLVD (SR50) | F9: =Sheet1!F20 -> 2U | G9: =Sheet1!H20 -> 2U | H9: =Sheet1!Z20 -> C | M9: =Sheet1!AI20 -> 4020 | R9: =Sheet1!P20 -> 7287 | X9: =Sheet1!AS20 -> 656 | Y9: =Sheet1!AT20 -> 0.163
B10: =Sheet1!A21 -> 10820 | C10: =Sheet1!C21 -> TREIMAN BLVD (US301/SR35) | D10: =Sheet1!D21 -> CORTEZ BLVD (SR50) | E10: =Sheet1!E21 -> RIDGE MANOR BLVD | F10: =Sheet1!F21 -> 2U | G10: =Sheet1!H21 -> 2U | H10: =Sheet1!Z21 -> C | M10: =Sheet1!AI21 -> 820 | R10: =Sheet1!P21 -> 8669 | X10: =Sheet1!AS21 -> 780 | Y10: =Sheet1!AT21 -> 0.951
B11: =Sheet1!A22 -> 10830 | C11: =Sheet1!C22 -> TREIMAN BLVD (US301/SR35) | D11: =Sheet1!D22 -> RIDGE MANOR BLVD | E11: =Sheet1!E22 -> SUMTER COUNTY LINE | F11: =Sheet1!F22 -> 2U | G11: =Sheet1!H22 -> 4D | H11: =Sheet1!Z22 -> C | M11: =Sheet1!AI22 -> 1490 | R11: =Sheet1!P22 -> 5327 | X11: =Sheet1!AS22 -> 479 | Y11: =Sheet1!AT22 -> 0.321
B12: =Sheet1!A23 -> 10060 | C12: =Sheet1!C23 -> BROAD ST (US41/SR45) | D12: =Sheet1!D23 -> COUNTY LINE RD | E12: =Sheet1!E23 -> AYERS RD | F12: =Sheet1!F23 -> 2U | G12: =Sheet1!H23 -> 4D | H12: =Sheet1!Z23 -> C | M12: =Sheet1!AI23 -> 1510 | R12: =Sheet1!P23 -> 17465 | X12: =Sheet1!AS23 -> 1572 | Y12: =Sheet1!AT23 -> 1.041
B13: =Sheet1!A24 -> 10070.1 | C13: =Sheet1!C24 -> BROAD ST (US41/SR45) | D13: =Sheet1!D24 -> AYERS RD | E13: =Sheet1!E24 -> SGT LEA MILLS BLVD | F13: =Sheet1!F24 -> 4D | G13: =Sheet1!H24 -> 4D | H13: =Sheet1!Z24 -> C | M13: =Sheet1!AI24 -> 3420 | R13: =Sheet1!P24 -> 17233 | X13: =Sheet1!AS24 -> 1551 | Y13: =Sheet1!AT24 -> 0.454
B14: =Sheet1!A25 -> 10070.2 | C14: =Sheet1!C25 -> BROAD ST (US41/SR45) | D14: =Sheet1!D25 -> SGT LEA MILLS BLVD | E14: =Sheet1!E25 -> SPRING HILL DR | F14: =Sheet1!F25 -> 4D | G14: =Sheet1!H25 -> 6D | H14: =Sheet1!Z25 -> C | M14: =Sheet1!AI25 -> 3420 | R14: =Sheet1!P25 -> 17233 | X14: =Sheet1!AS25 -> 1551 | Y14: =Sheet1!AT25 -> 0.454
B15: =Sheet1!A26 -> 10080 | C15: =Sheet1!C26 -> BROAD ST (US41/SR45) | D15: =Sheet1!D26 -> SPRING HILL DR | E15: =Sheet1!E26 -> POWELL RD | F15: =Sheet1!F26 -> 4D | G15: =Sheet1!H26 -> 6D | H15: =Sheet1!Z26 -> C | M15: =Sheet1!AI26 -> 3420 | R15: =Sheet1!P26 -> 25487 | X15: =Sheet1!AS26 -> 2294 | Y15: =Sheet1!AT26 -> 0.671
B16: =Sheet1!A27 -> 10090 | C16: =Sheet1!C27 -> BROAD ST (US41/SR45) | D16: =Sheet1!D27 -> POWELL RD | E16: =Sheet1!E27 -> PINE CABIN RD | F16: =Sheet1!F27 -> 6D | G16: =Sheet1!H27 -> 6D | H16: =Sheet1!Z27 -> C | M16: =Sheet1!AI27 -> 5250 | R16: =Sheet1!P27 -> 27904 | X16: =Sheet1!AS27 -> 2511 | Y16: =Sheet1!AT27 -> 0.478
B17: =Sheet1!A28 -> 10100 | C17: =Sheet1!C28 -> BROAD ST (US41/SR45) | D17: =Sheet1!D28 -> PINE CABIN RD | E17: =Sheet1!E28 -> HENNES COVE | F17: =Sheet1!F28 -> 6D | G17: =Sheet1!H28 -> 6D | H17: =Sheet1!Z28 -> C | M17: =Sheet1!AI28 -> 5250 | R17: =Sheet1!P28 -> 27904 | X17: =Sheet1!AS28 -> 2511 | Y17: =Sheet1!AT28 -> 0.478
B18: =Sheet1!A29 -> 10110.1 | C18: =Sheet1!C29 -> BROAD ST (US41/SR45) | D18: =Sheet1!D29 -> HENNES COVE | E18: =Sheet1!E29 -> JOHN MARTIN LN | F18: =Sheet1!F29 -> 6D | G18: =Sheet1!H29 -> 6D | H18: =Sheet1!Z29 -> C | M18: =Sheet1!AI29 -> 5250 | R18: =Sheet1!P29 -> 27904 | X18: =Sheet1!AS29 -> 2511 | Y18: =Sheet1!AT29 -> 0.478
B19: =Sheet1!A30 -> 10110.2 | C19: =Sheet1!C30 -> BROAD ST (US41/SR45) | D19: =Sheet1!D30 -> JOHN MARTIN LN | E19: =Sheet1!E30 -> VFW RD | F19: =Sheet1!F30 -> 6D | G19: =Sheet1!H30 -> 6D | H19: =Sheet1!Z30 -> C | M19: =Sheet1!AI30 -> 5250 | R19: =Sheet1!P30 -> 27904 | X19: =Sheet1!AS30 -> 2511 | Y19: =Sheet1!AT30 -> 0.478
B20: =Sheet1!A31 -> 10115 | C20: =Sheet1!C31 -> BROAD ST (US41/SR45) | D20: =Sheet1!D31 -> VFW RD | E20: =Sheet1!E31 -> WISCON RD | F20: =Sheet1!F31 -> 6D | G20: =Sheet1!H31 -> 6D | H20: =Sheet1!Z31 -> C | M20: =Sheet1!AI31 -> 5250 | R20: =Sheet1!P31 -> 27904 | X20: =Sheet1!AS31 -> 2511 | Y20: =Sheet1!AT31 -> 0.478
... B369: =Sheet1!A380 -> 4410.2 | C369: =Sheet1!C380 -> OSOWAW BLVD (CR595) | D369: =Sheet1!D380 -> 1600 FT N OF ALOHA LN | E369: =Sheet1!E380 -> SHOAL LINE BLVD | F369: =Sheet1!F380 -> 2U | G369: =Sheet1!H380 -> 2U | H369: =Sheet1!Z380 -> D | M369: =Sheet1!AI380 -> 1818 | R369: =Sheet1!P380 -> 1931 | X369: =Sheet1!AS380 -> 174 | Y369: =Sheet1!AT380 -> 0.096
