Workbook

Sheet Table001 (Page 1-6)
A1: SEGMENT ID | B1: ROAD NAME | C1: FROM | D1: TO | E1: LANES (2023) | F1: FUNCTIONAL CLASSIFICATION | G1: FLOW | H1: FDOT CLASS | I1: DAILY SERVICE VOLUME (2023) | J1: PEAK HOUR DIRECTIONAL SERVICE VOLUME (2023) | K1: LANES (2028) | L1: DAILY SERVICE VOLUME (2028) | M1: PEAK HOUR DIRECTIONAL SERVICE VOLUME (2028) | N1: URBAN / RURAL | O1: DIVIDED / UNDIVIDED | P1: MAINTAINING AGENCY | Q1: NHS | R1: ADOPTED LOS STANDARD | S1: 2023 AADT | T1: 2023 DAILY V/MSV | U1: 2023 DAILY LOS | V1: GROWTH RATE | W1: 2028 AADT | X1: 2028 DAILY V/MSV | Y1: 2028 DAILY LOS
A2: 1010 | B2: SE 92 PLACE LOOP | C2: SR 35 | D2: US 441 | E2: 4 | F2: ARTERIAL | G2: UNINTERRUPTED | I2: 67770 | J2: 3357 | K2: 4 | L2: 67770 | M2: 3357 | N2: Urban | O2: D | P2: COUNTY | Q2: Other CMP Network Roadway | R2: E | S2: 12,400 | T2: 0.18 | U2: B | V2: 0.01 | W2: 13,100 | X2: 0.19 | Y2: B
A3: 1020 | B3: CR 21 | C3: CR 315 | D3: COUNTY LINE | E3: 2 | F3: COLLECTOR | G3: UNINTERRUPTED | I3: 19170 | J3: 999 | K3: 2 | L3: 19170 | M3: 999 | N3: Rural | O3: U | P3: COUNTY | Q3: Other CMP Network Roadway | R3: D | S3: Not Counted | T3: N/A | U3: N/A | V3: 0.01 | W3: Not Counted | X3: N/A | Y3: N/A
A4: 1030.1 | B4: CR 225 | C4: US 27 | D4: CR 326 | E4: 2 | F4: COLLECTOR | G4: UNINTERRUPTED | I4: 9270 | J4: 486 | K4: 2 | L4: 9270 | M4: 486 | N4: Rural | O4: U | P4: COUNTY | Q4: Other CMP Network Roadway | R4: B | S4: 1,500 | T4: 0.16 | U4: B | V4: 0.0527 | W4: 1,900 | X4: 0.20 | Y4: B
A5: 1030.4 | B5: CR 225 | C5: CR 326 | D5: CR 316 | E5: 2 | F5: COLLECTOR | G5: UNINTERRUPTED | I5: 9270 | J5: 486 | K5: 2 | L5: 9270 | M5: 486 | N5: Rural | O5: U | P5: COUNTY | Q5: Other CMP Network Roadway | R5: B | S5: 1,500 | T5: 0.16 | U5: B | V5: 0.0527 | W5: 1,900 | X5: 0.20 | Y5: B
A6: 1040.1 | B6: CR 225 | C6: CR 316 | D6: CR 318 | E6: 2 | F6: COLLECTOR | G6: UNINTERRUPTED | I6: 9270 | J6: 486 | K6: 2 | L6: 9270 | M6: 486 | N6: Rural | O6: U | P6: COUNTY | Q6: Other CMP Network Roadway | R6: B | S6: 1,500 | T6: 0.16 | U6: B | V6: 0.0527 | W6: 1,900 | X6: 0.20 | Y6: B
A7: 1050 | B7: CR 225A | C7: US 27 | D7: CR 326 | E7: 2 | F7: COLLECTOR | G7: INTERRUPTED | I7: 10224 | J7: 533 | K7: 2 | L7: 10224 | M7: 533 | N7: Rural | O7: U | P7: COUNTY | Q7: Other CMP Network Roadway | R7: D | S7: 7,100 | T7: 0.69 | U7: C | V7: 0.01 | W7: 7,400 | X7: 0.72 | Y7: C
A8: 1060 | B8: CR 225A | C8: CR 326 | D8: CR 329 | E8: 2 | F8: COLLECTOR | G8: UNINTERRUPTED | I8: 9270 | J8: 486 | K8: 2 | L8: 9270 | M8: 486 | N8: Rural | O8: U | P8: COUNTY | Q8: Other CMP Network Roadway | R8: B | S8: 3,100 | T8: 0.33 | U8: B | V8: 0.01 | W8: 3,300 | X8: 0.36 | Y8: B
A9: 1070 | B9: CR 25 | C9: COUNTY LINE | D9: CR 42 | E9: 2 | F9: COLLECTOR | G9: INTERRUPTED | H9: 1 | I9: 12744 | J9: 634 | K9: 2 | L9: 12744 | M9: 634 | N9: Urban | O9: U | P9: COUNTY | Q9: Other CMP Network Roadway | R9: E | S9: 11,300 | T9: 0.89 | U9: C | V9: 0.0111 | W9: 12,000 | X9: 0.94 | Y9: C
A10: 1080.1 | B10: CR 25 | C10: CR 42 | D10: SE 128 PL RD | E10: 2 | F10: COLLECTOR | G10: UNINTERRUPTED | I10: 29340 | J10: 1449 | K10: 2 | L10: 29340 | M10: 1449 | N10: Urban | O10: U | P10: COUNTY | Q10: Other CMP Network Roadway | R10: E | S10: 7,800 | T10: 0.27 | U10: B | V10: 0.01 | W10: 8,200 | X10: 0.28 | Y10: B
A11: 1080.3 | B11: CR 25 | C11: SE 128 PL RD | D11: SE 135 AV | E11: 2 | F11: COLLECTOR | G11: UNINTERRUPTED | I11: 29340 | J11: 1449 | K11: 2 | L11: 29340 | M11: 1449 | N11: Urban | O11: U | P11: COUNTY | Q11: Other CMP Network Roadway | R11: E | S11: 7,800 | T11: 0.27 | U11: B | V11: 0.01 | W11: 8,200 | X11: 0.28 | Y11: B
A12: 1090.1 | B12: CR 25 | C12: SE 135 AV | D12: CR 464 | E12: 2 | F12: COLLECTOR | G12: UNINTERRUPTED | I12: 29340 | J12: 1449 | K12: 2 | L12: 29340 | M12: 1449 | N12: Urban | O12: U | P12: COUNTY | Q12: Other CMP Network Roadway | R12: E | S12: 7,800 | T12: 0.27 | U12: B | V12: 0.01 | W12: 8,200 | X12: 0.28 | Y12: B
A13: 1100.1 | B13: CR 25 | C13: CR 464 | D13: SE 108 TER RD | E13: 2 | F13: COLLECTOR | G13: UNINTERRUPTED | I13: 29340 | J13: 1449 | K13: 2 | L13: 29340 | M13: 1449 | N13: Urban | O13: U | P13: COUNTY | Q13: Other CMP Network Roadway | R13: E | S13: 6,100 | T13: 0.21 | U13: B | V13: 0.01 | W13: 6,400 | X13: 0.22 | Y13: B
A14: 1100.4 | B14: CR 25 | C14: SE 108 TER RD | D14: SE 92 PL LOOP | E14: 2 | F14: COLLECTOR | G14: UNINTERRUPTED | I14: 29340 | J14: 1449 | K14: 2 | L14: 29340 | M14: 1449 | N14: Urban | O14: U | P14: COUNTY | Q14: Other CMP Network Roadway | R14: E | S14: 7,000 | T14: 0.24 | U14: B | V14: 0.0627 | W14: 9,500 | X14: 0.32 | Y14: B
A15: 1110.4 | B15: CR 25 | C15: SE 92 PL LOOP | D15: SE 110 ST | E15: 2 | F15: COLLECTOR | G15: UNINTERRUPTED | I15: 29340 | J15: 1449 | K15: 2 | L15: 29340 | M15: 1449 | N15: Urban | O15: U | P15: COUNTY | Q15: Other CMP Network Roadway | R15: E | S15: 9,900 | T15: 0.34 | U15: B | V15: 0.01 | W15: 10,400 | X15: 0.35 | Y15: B
A16: 1120 | B16: US 441 | C16: NE 28 ST | D16: CR 25A (S) | E16: 4 | F16: ARTERIAL | G16: INTERRUPTED | I16: 40352 | J16: 1996 | K16: 4 | L16: 40352 | M16: 1996 | N16: Urban | O16: D | P16: STATE | Q16: NHS - Non-Interstate Roadway | R16: D | S16: 18,300 | T16: 0.45 | U16: C | V16: 0.01 | W16: 19,200 | X16: 0.48 | Y16: C
A17: 1130 | B17: CR 25A | C17: US 441 (S) | D17: SR 326 | E17: 2 | F17: COLLECTOR | G17: INTERRUPTED | H17: 1 | I17: 12744 | J17: 634 | K17: 2 | L17: 12744 | M17: 634 | N17: Urban | O17: U | P17: COUNTY | Q17: Other CMP Network Roadway | R17: E | S17: 5,400 | T17: 0.42 | U17: C | V17: 0.0158 | W17: 5,800 | X17: 0.46 | Y17: C
A18: 1150.1 | B18: CR 25A | C18: SR 326 | D18: URBAN AREA BOUNDARY | E18: 2 | F18: COLLECTOR | G18: UNINTERRUPTED | I18: 29340 | J18: 1449 | K18: 2 | L18: 29340 | M18: 1449 | N18: Urban | O18: U | P18: COUNTY | Q18: Other CMP Network Roadway | R18: E | S18: 8,200 | T18: 0.28 | U18: B | V18: 0.01 | W18: 8,600 | X18: 0.29 | Y18: B
A19: 1150.2 | B19: CR 25A | C19: URBAN AREA BOUNDARY | D19: CR 329 | E19: 2 | F19: COLLECTOR | G19: UNINTERRUPTED | I19: 19170 | J19: 999 | K19: 2 | L19: 19170 | M19: 999 | N19: Rural | O19: U | P19: COUNTY | Q19: Other CMP Network Roadway | R19: D | S19: 8,200 | T19: 0.43 | U19: B | V19: 0.01 | W19: 8,600 | X19: 0.45 | Y19: B
A20: 1160.2 | B20: CR 25A | C20: CR 316 | D20: US 441 | E20: 2 | F20: COLLECTOR | G20: UNINTERRUPTED | I20: 9270 | J20: 486 | K20: 2 | L20: 9270 | M20: 486 | N20: Rural | O20: U | P20: COUNTY | Q20: Other CMP Network Roadway | R20: B | S20: 3,300 | T20: 0.36 | U20: B | V20: 0.0845 | W20: 4,900 | X20: 0.53 | Y20: B
A21: 1160.3 | B21: CR 25A | C21: CR 329 | D21: CR 316 | E21: 2 | F21: COLLECTOR | G21: UNINTERRUPTED | I21: 14130 | J21: 738 | K21: 2 | L21: 14130 | M21: 738 | N21: Rural | O21: U | P21: COUNTY | Q21: Other CMP Network Roadway | R21: C | S21: 3,300 | T21: 0.23 | U21: B | V21: 0.0845 | W21: 4,900 | X21: 0.35 | Y21: B
A22: 1170 | B22: CR 25A | C22: US 441 | D22: CR 25 | E22: 2 | F22: COLLECTOR | G22: UNINTERRUPTED | I22: 29340 | J22: 1449 | K22: 2 | L22: 29340 | M22: 1449 | N22: Urban | O22: U | P22: COUNTY | Q22: Other CMP Network Roadway | R22: E | S22: Not Counted | T22: N/A | U22: N/A | V22: 0.01 | W22: Not Counted | X22: N/A | Y22: N/A
A23: 1180 | B23: CR 314 | C23: NE 7 ST | D23: SE 1 ST | E23: 2 | F23: COLLECTOR | G23: UNINTERRUPTED | I23: 19170 | J23: 999 | K23: 2 | L23: 19170 | M23: 999 | N23: Rural | O23: U | P23: COUNTY | Q23: Other CMP Network Roadway | R23: D | S23: 2,100 | T23: 0.11 | U23: B | V23: 0.01 | W23: 2,200 | X23: 0.11 | Y23: B
A24: 1190.1 | B24: CR 314 | C24: SE 1 ST | D24: SR 40 (E) | E24: 2 | F24: COLLECTOR | G24: UNINTERRUPTED | I24: 19170 | J24: 999 | K24: 2 | L24: 19170 | M24: 999 | N24: Rural | O24: U | P24: COUNTY | Q24: Other CMP Network Roadway | R24: D | S24: 2,000 | T24: 0.1 | U24: B | V24: 0.035 | W24: 2,300 | X24: 0.12 | Y24: B
A25: 1200 | B25: CR 314 | C25: SR 40 (E) | D25: CR 314A | E25: 2 | F25: COLLECTOR | G25: UNINTERRUPTED | I25: 19170 | J25: 999 | K25: 2 | L25: 19170 | M25: 999 | N25: Rural | O25: U | P25: COUNTY | Q25: Other CMP Network Roadway | R25: D | S25: 3,100 | T25: 0.16 | U25: B | V25: 0.01 | W25: 3,300 | X25: 0.17 | Y25: B
A26: 1210.2 | B26: CR 314 | C26: CR 314A | D26: SR 19 | E26: 2 | F26: COLLECTOR | G26: UNINTERRUPTED | I26: 19170 | J26: 999 | K26: 2 | L26: 19170 | M26: 999 | N26: Rural | O26: U | P26: COUNTY | Q26: Other CMP Network Roadway | R26: D | S26: 3,400 | T26: 0.18 | U26: B | V26: 0.01 | W26: 3,600 | X26: 0.19 | Y26: B
A27: 1220 | B27: CR 314A | C27: CR 464C | D27: SE 180 AV | E27: 2 | F27: COLLECTOR | G27: UNINTERRUPTED | I27: 19170 | J27: 999 | K27: 2 | L27: 19170 | M27: 999 | N27: Rural | O27: U | P27: COUNTY | Q27: Other CMP Network Roadway | R27: D | S27: 5,700 | T27: 0.3 | U27: B | V27: 0.1397 | W27: 11,000 | X27: 0.57 | Y27: C
A28: 1230.1 | B28: CR 314A | C28: SE 180 AV | D28: SR 40 | E28: 2 | F28: COLLECTOR | G28: UNINTERRUPTED | I28: 19170 | J28: 999 | K28: 2 | L28: 19170 | M28: 999 | N28: Rural | O28: U | P28: COUNTY | Q28: Other CMP Network Roadway | R28: D | S28: 4,700 | T28: 0.25 | U28: B | V28: 0.01 | W28: 5,000 | X28: 0.26 | Y28: B
A29: 1240 | B29: CR 314A | C29: SR 40 | D29: CR 314 | E29: 2 | F29: COLLECTOR | G29: UNINTERRUPTED | I29: 19170 | J29: 999 | K29: 2 | L29: 19170 | M29: 999 | N29: Rural | O29: U | P29: COUNTY | Q29: Other CMP Network Roadway | R29: D | S29: 1,800 | T29: 0.09 | U29: B | V29: 0.01 | W29: 1,900 | X29: 0.10 | Y29: B
... A63: 1470 | B63: CR 336 | C63: COUNTY LINE | D63: CR 40 | E63: 2 | F63: COLLECTOR | G63: UNINTERRUPTED | I63: 19170 | J63: 999 | K63: 2 | L63: 19170 | M63: 999 | N63: Rural | O63: U | P63: COUNTY | Q63: Other CMP Network Roadway | R63: D | S63: Not Counted | T63: N/A | U63: N/A | V63: 0.01 | W63: Not Counted | X63: N/A | Y63: N/A
A64: 1480 | B64: CR 35 | C64: SR 40 | D64: NE 35 ST | E64: 2 | F64: COLLECTOR | G64: INTERRUPTED | H64: 2 | I64: 11232 | J64: 576 | K64: 2 | L64: 11232 | M64: 576 | N64: Urban | O64: U | P64: COUNTY | Q64: Other CMP Network Roadway | R64: E | S64: 9,600 | T64: 0.85 | U64: D | V64: 0.0252 | W64: 10,900 | X64: 0.97 | Y64: E
A65: 1490 | B65: CR 35 | C65: NE 35 ST | D65: NE 58 AV | E65: 2 | F65: COLLECTOR | G65: INTERRUPTED | H65: 1 | I65: 12744 | J65: 634 | K65: 2 | L65: 12744 | M65: 634 | N65: Urban | O65: U | P65: COUNTY | Q65: Other CMP Network Roadway | R65: E | S65: 6,000 | T65: 0.47 | U65: C | V65: 0.0261 | W65: 6,800 | X65: 0.53 | Y65: C
A66: 1500 | B66: CR 35 | C66: NE 58 AV | D66: SR 326 | E66: 2 | F66: COLLECTOR | G66: UNINTERRUPTED | I66: 29340 | J66: 1449 | K66: 2 | L66: 29340 | M66: 1449 | N66: Urban | O66: U | P66: COUNTY | Q66: Other CMP Network Roadway | R66: E | S66: 6,000 | T66: 0.2 | U66: B | V66: 0.0301 | W66: 6,900 | X66: 0.24 | Y66: B
A67: 1510 | B67: CR 35 | C67: SR 326 | D67: NE 97TH ST RD | E67: 2 | F67: COLLECTOR | G67: UNINTERRUPTED | I67: 25650 | J67: 1341 | K67: 2 | L67: 25650 | M67: 1341 | N67: Rural | O67: U | P67: COUNTY | Q67: Other CMP Network Roadway | R67: E | S67: 3,100 | T67: 0.12 | U67: B | V67: 0.0371 | W67: 3,700 | X67: 0.14 | Y67: B
A68: 1520.2 | B68: CR 40 | C68: COUNTY LINE (W) | D68: CR 336 | E68: 2 | F68: COLLECTOR | G68: UNINTERRUPTED | I68: 19170 | J68: 999 | K68: 2 | L68: 19170 | M68: 999 | N68: Rural | O68: U | P68: COUNTY | Q68: Other CMP Network Roadway | R68: D | S68: 3,700 | T68: 0.19 | U68: B | V68: 0.091 | W68: 5,700 | X68: 0.30 | Y68: B
A69: 1530 | B69: CR 40 | C69: CR 336 | D69: URBAN AREA BOUNDRY | E69: 2 | F69: COLLECTOR | G69: UNINTERRUPTED | I69: 19170 | J69: 999 | K69: 2 | L69: 19170 | M69: 999 | N69: Rural | O69: U | P69: COUNTY | Q69: Other CMP Network Roadway | R69: D | S69: 3,400 | T69: 0.18 | U69: B | V69: 0.01 | W69: 3,600 | X69: 0.19 | Y69: B
A70: 1540.1 | B70: CR 40 | C70: URBAN AREA BOUNDRY | D70: SW ROLLING HILLS RD | E70: 2 | F70: COLLECTOR | G70: UNINTERRUPTED | I70: 29340 | J70: 1449 | K70: 2 | L70: 29340 | M70: 1449 | N70: Urban | O70: U | P70: COUNTY | Q70: Other CMP Network Roadway | R70: E | S70: 3,700 | T70: 0.13 | U70: B | V70: 0.01 | W70: 3,900 | X70: 0.13 | Y70: B
A71: 1550.1 | B71: CR 42 | C71: CR 475 | D71: US 301 | E71: 2 | F71: COLLECTOR | G71: UNINTERRUPTED | I71: 19170 | J71: 999 | K71: 2 | L71: 19170 | M71: 999 | N71: Rural | O71: U | P71: COUNTY | Q71: Other CMP Network Roadway | R71: D | S71: 5,300 | T71: 0.28 | U71: B | V71: 0.01 | W71: 5,500 | X71: 0.29 | Y71: B
A72: 1560 | B72: CR 42 | C72: US 301 | D72: SE 77 AV | E72: 4 | F72: ARTERIAL | G72: INTERRUPTED | H72: 1 | I72: 35820 | J72: 1800 | K72: 4 | L72: 35820 | M72: 1800 | N72: Urban | O72: D | P72: COUNTY | Q72: Other CMP Network Roadway | R72: E | S72: 18,300 | T72: 0.51 | U72: C | V72: 0.0505 | W72: 23,400 | X72: 0.65 | Y72: C
A73: 1570 | B73: CR 42 | C73: SE 77 AV | D73: US 441 | E73: 4 | F73: ARTERIAL | G73: INTERRUPTED | H73: 1 | I73: 35820 | J73: 1800 | K73: 4 | L73: 35820 | M73: 1800 | N73: Urban | O73: D | P73: COUNTY | Q73: Other CMP Network Roadway | R73: E | S73: 18,300 | T73: 0.51 | U73: C | V73: 0.0505 | W73: 23,400 | X73: 0.65 | Y73: C
...

Sheet Input
L6: Exiting | O6: Improved | R6: =$AA$2&" Existing Conditions" -> Existing Conditions | AJ6: Daily/2way/Directional per Agency
B7: Seg | C7: Segment Information | F7: Exist | G7: Imp | H7: LOS | I7: Functional | J7: Facility | K7: Context | L7: Daily | M7: 2-Way | N7: Dir | O7: Daily | P7: Peak | Q7: Dir | R7: Daily | U7: AM 2-Way | X7: PM 2-Way | AA7: AM Directional | AE7: PM Directional | AI7: GR | AJ7: Adjusted Service Volumes
B8: ID | C8: Roadway | D8: From | E8: To | F8: Lns | G8: Lns | H8: Std | I8: Class | J8: Type | K8: Classification | L8: Cap | M8: Cap | N8: Cap | O8: Cap | P8: Cap | Q8: Cap | R8: Volume | S8: V/C | T8: LOS | U8: Vol | V8: V/C | W8: LOS | X8: Vol | Y8: V/C | Z8: LOS | AA8: NB/EB | AB8: SB/WB | AC8: V/C | AD8: LOS | AE8: NB/EB | AF8: SB/WB | AG8: V/C | AH8: LOS | AJ8: B | AK8: C | AL8: D | AM8: E
B9: ='Table001 (Page 1-6)'!A2 -> 1010 | C9: ='Table001 (Page 1-6)'!B2 -> SE 92 PLACE LOOP | D9: ='Table001 (Page 1-6)'!C2 -> SR 35 | E9: ='Table001 (Page 1-6)'!D2 -> US 441 | F9: ='Table001 (Page 1-6)'!E2 -> 4 | G9: ='Table001 (Page 1-6)'!K2 -> 4 | H9: ='Table001 (Page 1-6)'!R2 -> E | I9: ='Table001 (Page 1-6)'!F2 -> ARTERIAL | L9: ='Table001 (Page 1-6)'!I2 -> 67770 | N9: ='Table001 (Page 1-6)'!J2 -> 3357 | O9: ='Table001 (Page 1-6)'!L2 -> 67770 | Q9: ='Table001 (Page 1-6)'!M2 -> 3357 | R9: ='Table001 (Page 1-6)'!S2 -> 12,400 | S9: ='Table001 (Page 1-6)'!T2 -> 0.18 | T9: ='Table001 (Page 1-6)'!U2 -> B | AI9: =('Table001 (Page 1-6)'!V2)*100 -> 1
B10: ='Table001 (Page 1-6)'!A3 -> 1020 | C10: ='Table001 (Page 1-6)'!B3 -> CR 21 | D10: ='Table001 (Page 1-6)'!C3 -> CR 315 | E10: ='Table001 (Page 1-6)'!D3 -> COUNTY LINE | F10: ='Table001 (Page 1-6)'!E3 -> 2 | G10: ='Table001 (Page 1-6)'!K3 -> 2 | H10: ='Table001 (Page 1-6)'!R3 -> D | I10: ='Table001 (Page 1-6)'!F3 -> COLLECTOR | L10: ='Table001 (Page 1-6)'!I3 -> 19170 | N10: ='Table001 (Page 1-6)'!J3 -> 999 | O10: ='Table001 (Page 1-6)'!L3 -> 19170 | Q10: ='Table001 (Page 1-6)'!M3 -> 999 | R10: ='Table001 (Page 1-6)'!S3 -> Not Counted | S10: ='Table001 (Page 1-6)'!T3 -> N/A | T10: ='Table001 (Page 1-6)'!U3 -> N/A | AI10: =('Table001 (Page 1-6)'!V3)*100 -> 1
B11: ='Table001 (Page 1-6)'!A4 -> 1030.1 | C11: ='Table001 (Page 1-6)'!B4 -> CR 225 | D11: ='Table001 (Page 1-6)'!C4 -> US 27 | E11: ='Table001 (Page 1-6)'!D4 -> CR 326 | F11: ='Table001 (Page 1-6)'!E4 -> 2 | G11: ='Table001 (Page 1-6)'!K4 -> 2 | H11: ='Table001 (Page 1-6)'!R4 -> B | I11: ='Table001 (Page 1-6)'!F4 -> COLLECTOR | L11: ='Table001 (Page 1-6)'!I4 -> 9270 | N11: ='Table001 (Page 1-6)'!J4 -> 486 | O11: ='Table001 (Page 1-6)'!L4 -> 9270 | Q11: ='Table001 (Page 1-6)'!M4 -> 486 | R11: ='Table001 (Page 1-6)'!S4 -> 1,500 | S11: ='Table001 (Page 1-6)'!T4 -> 0.16 | T11: ='Table001 (Page 1-6)'!U4 -> B | AI11: =('Table001 (Page 1-6)'!V4)*100 -> 5.27
B12: ='Table001 (Page 1-6)'!A5 -> 1030.4 | C12: ='Table001 (Page 1-6)'!B5 -> CR 225 | D12: ='Table001 (Page 1-6)'!C5 -> CR 326 | E12: ='Table001 (Page 1-6)'!D5 -> CR 316 | F12: ='Table001 (Page 1-6)'!E5 -> 2 | G12: ='Table001 (Page 1-6)'!K5 -> 2 | H12: ='Table001 (Page 1-6)'!R5 -> B | I12: ='Table001 (Page 1-6)'!F5 -> COLLECTOR | L12: ='Table001 (Page 1-6)'!I5 -> 9270 | N12: ='Table001 (Page 1-6)'!J5 -> 486 | O12: ='Table001 (Page 1-6)'!L5 -> 9270 | Q12: ='Table001 (Page 1-6)'!M5 -> 486 | R12: ='Table001 (Page 1-6)'!S5 -> 1,500 | S12: ='Table001 (Page 1-6)'!T5 -> 0.16 | T12: ='Table001 (Page 1-6)'!U5 -> B | AI12: =('Table001 (Page 1-6)'!V5)*100 -> 5.27
B13: ='Table001 (Page 1-6)'!A6 -> 1040.1 | C13: ='Table001 (Page 1-6)'!B6 -> CR 225 | D13: ='Table001 (Page 1-6)'!C6 -> CR 316 | E13: ='Table001 (Page 1-6)'!D6 -> CR 318 | F13: ='Table001 (Page 1-6)'!E6 -> 2 | G13: ='Table001 (Page 1-6)'!K6 -> 2 | H13: ='Table001 (Page 1-6)'!R6 -> B | I13: ='Table001 (Page 1-6)'!F6 -> COLLECTOR | L13: ='Table001 (Page 1-6)'!I6 -> 9270 | N13: ='Table001 (Page 1-6)'!J6 -> 486 | O13: ='Table001 (Page 1-6)'!L6 -> 9270 | Q13: ='Table001 (Page 1-6)'!M6 -> 486 | R13: ='Table001 (Page 1-6)'!S6 -> 1,500 | S13: ='Table001 (Page 1-6)'!T6 -> 0.16 | T13: ='Table001 (Page 1-6)'!U6 -> B | AI13: =('Table001 (Page 1-6)'!V6)*100 -> 5.27
B14: ='Table001 (Page 1-6)'!A7 -> 1050 | C14: ='Table001 (Page 1-6)'!B7 -> CR 225A | D14: ='Table001 (Page 1-6)'!C7 -> US 27 | E14: ='Table001 (Page 1-6)'!D7 -> CR 326 | F14: ='Table001 (Page 1-6)'!E7 -> 2 | G14: ='Table001 (Page 1-6)'!K7 -> 2 | H14: ='Table001 (Page 1-6)'!R7 -> D | I14: ='Table001 (Page 1-6)'!F7 -> COLLECTOR | L14: ='Table001 (Page 1-6)'!I7 -> 10224 | N14: ='Table001 (Page 1-6)'!J7 -> 533 | O14: ='Table001 (Page 1-6)'!L7 -> 10224 | Q14: ='Table001 (Page 1-6)'!M7 -> 533 | R14: ='Table001 (Page 1-6)'!S7 -> 7,100 | S14: ='Table001 (Page 1-6)'!T7 -> 0.69 | T14: ='Table001 (Page 1-6)'!U7 -> C | AI14: =('Table001 (Page 1-6)'!V7)*100 -> 1
B15: ='Table001 (Page 1-6)'!A8 -> 1060 | C15: ='Table001 (Page 1-6)'!B8 -> CR 225A | D15: ='Table001 (Page 1-6)'!C8 -> CR 326 | E15: ='Table001 (Page 1-6)'!D8 -> CR 329 | F15: ='Table001 (Page 1-6)'!E8 -> 2 | G15: ='Table001 (Page 1-6)'!K8 -> 2 | H15: ='Table001 (Page 1-6)'!R8 -> B | I15: ='Table001 (Page 1-6)'!F8 -> COLLECTOR | L15: ='Table001 (Page 1-6)'!I8 -> 9270 | N15: ='Table001 (Page 1-6)'!J8 -> 486 | O15: ='Table001 (Page 1-6)'!L8 -> 9270 | Q15: ='Table001 (Page 1-6)'!M8 -> 486 | R15: ='Table001 (Page 1-6)'!S8 -> 3,100 | S15: ='Table001 (Page 1-6)'!T8 -> 0.33 | T15: ='Table001 (Page 1-6)'!U8 -> B | AI15: =('Table001 (Page 1-6)'!V8)*100 -> 1
B16: ='Table001 (Page 1-6)'!A9 -> 1070 | C16: ='Table001 (Page 1-6)'!B9 -> CR 25 | D16: ='Table001 (Page 1-6)'!C9 -> COUNTY LINE | E16: ='Table001 (Page 1-6)'!D9 -> CR 42 | F16: ='Table001 (Page 1-6)'!E9 -> 2 | G16: ='Table001 (Page 1-6)'!K9 -> 2 | H16: ='Table001 (Page 1-6)'!R9 -> E | I16: ='Table001 (Page 1-6)'!F9 -> COLLECTOR | L16: ='Table001 (Page 1-6)'!I9 -> 12744 | N16: ='Table001 (Page 1-6)'!J9 -> 634 | O16: ='Table001 (Page 1-6)'!L9 -> 12744 | Q16: ='Table001 (Page 1-6)'!M9 -> 634 | R16: ='Table001 (Page 1-6)'!S9 -> 11,300 | S16: ='Table001 (Page 1-6)'!T9 -> 0.89 | T16: ='Table001 (Page 1-6)'!U9 -> C | AI16: =('Table001 (Page 1-6)'!V9)*100 -> 1.11
B17: ='Table001 (Page 1-6)'!A10 -> 1080.1 | C17: ='Table001 (Page 1-6)'!B10 -> CR 25 | D17: ='Table001 (Page 1-6)'!C10 -> CR 42 | E17: ='Table001 (Page 1-6)'!D10 -> SE 128 PL RD | F17: ='Table001 (Page 1-6)'!E10 -> 2 | G17: ='Table001 (Page 1-6)'!K10 -> 2 | H17: ='Table001 (Page 1-6)'!R10 -> E | I17: ='Table001 (Page 1-6)'!F10 -> COLLECTOR | L17: ='Table001 (Page 1-6)'!I10 -> 29340 | N17: ='Table001 (Page 1-6)'!J10 -> 1449 | O17: ='Table001 (Page 1-6)'!L10 -> 29340 | Q17: ='Table001 (Page 1-6)'!M10 -> 1449 | R17: ='Table001 (Page 1-6)'!S10 -> 7,800 | S17: ='Table001 (Page 1-6)'!T10 -> 0.27 | T17: ='Table001 (Page 1-6)'!U10 -> B | AI17: =('Table001 (Page 1-6)'!V10)*100 -> 1
B18: ='Table001 (Page 1-6)'!A11 -> 1080.3 | C18: ='Table001 (Page 1-6)'!B11 -> CR 25 | D18: ='Table001 (Page 1-6)'!C11 -> SE 128 PL RD | E18: ='Table001 (Page 1-6)'!D11 -> SE 135 AV | F18: ='Table001 (Page 1-6)'!E11 -> 2 | G18: ='Table001 (Page 1-6)'!K11 -> 2 | H18: ='Table001 (Page 1-6)'!R11 -> E | I18: ='Table001 (Page 1-6)'!F11 -> COLLECTOR | L18: ='Table001 (Page 1-6)'!I11 -> 29340 | N18: ='Table001 (Page 1-6)'!J11 -> 1449 | O18: ='Table001 (Page 1-6)'!L11 -> 29340 | Q18: ='Table001 (Page 1-6)'!M11 -> 1449 | R18: ='Table001 (Page 1-6)'!S11 -> 7,800 | S18: ='Table001 (Page 1-6)'!T11 -> 0.27 | T18: ='Table001 (Page 1-6)'!U11 -> B | AI18: =('Table001 (Page 1-6)'!V11)*100 -> 1
B19: ='Table001 (Page 1-6)'!A12 -> 1090.1 | C19: ='Table001 (Page 1-6)'!B12 -> CR 25 | D19: ='Table001 (Page 1-6)'!C12 -> SE 135 AV | E19: ='Table001 (Page 1-6)'!D12 -> CR 464 | F19: ='Table001 (Page 1-6)'!E12 -> 2 | G19: ='Table001 (Page 1-6)'!K12 -> 2 | H19: ='Table001 (Page 1-6)'!R12 -> E | I19: ='Table001 (Page 1-6)'!F12 -> COLLECTOR | L19: ='Table001 (Page 1-6)'!I12 -> 29340 | N19: ='Table001 (Page 1-6)'!J12 -> 1449 | O19: ='Table001 (Page 1-6)'!L12 -> 29340 | Q19: ='Table001 (Page 1-6)'!M12 -> 1449 | R19: ='Table001 (Page 1-6)'!S12 -> 7,800 | S19: ='Table001 (Page 1-6)'!T12 -> 0.27 | T19: ='Table001 (Page 1-6)'!U12 -> B | AI19: =('Table001 (Page 1-6)'!V12)*100 -> 1
B20: ='Table001 (Page 1-6)'!A13 -> 1100.1 | C20: ='Table001 (Page 1-6)'!B13 -> CR 25 | D20: ='Table001 (Page 1-6)'!C13 -> CR 464 | E20: ='Table001 (Page 1-6)'!D13 -> SE 108 TER RD | F20: ='Table001 (Page 1-6)'!E13 -> 2 | G20: ='Table001 (Page 1-6)'!K13 -> 2 | H20: ='Table001 (Page 1-6)'!R13 -> E | I20: ='Table001 (Page 1-6)'!F13 -> COLLECTOR | L20: ='Table001 (Page 1-6)'!I13 -> 29340 | N20: ='Table001 (Page 1-6)'!J13 -> 1449 | O20: ='Table001 (Page 1-6)'!L13 -> 29340 | Q20: ='Table001 (Page 1-6)'!M13 -> 1449 | R20: ='Table001 (Page 1-6)'!S13 -> 6,100 | S20: ='Table001 (Page 1-6)'!T13 -> 0.21 | T20: ='Table001 (Page 1-6)'!U13 -> B | AI20: =('Table001 (Page 1-6)'!V13)*100 -> 1
... B562: ='Table001 (Page 1-6)'!A555 -> 9999 | C562: ='Table001 (Page 1-6)'!B555 -> SE 92 LOOP | D562: ='Table001 (Page 1-6)'!C555 -> CR 25 | E562: ='Table001 (Page 1-6)'!D555 -> SE 110 ST RD | F562: ='Table001 (Page 1-6)'!E555 -> 4 | G562: ='Table001 (Page 1-6)'!K555 -> 4 | H562: ='Table001 (Page 1-6)'!R555 -> E | I562: ='Table001 (Page 1-6)'!F555 -> COLLECTOR | L562: ='Table001 (Page 1-6)'!I555 -> 35820 | N562: ='Table001 (Page 1-6)'!J555 -> 792 | O562: ='Table001 (Page 1-6)'!L555 -> 35820 | Q562: ='Table001 (Page 1-6)'!M555 -> 1800 | R562: ='Table001 (Page 1-6)'!S555 -> Not Counted | S562: ='Table001 (Page 1-6)'!T555 -> N/A | T562: ='Table001 (Page 1-6)'!U555 -> N/A | AI562: =('Table001 (Page 1-6)'!V555)*100 -> 1

Sheet Sheet1
